[2022-01-06T10:12:19.931] [ERROR] ma-core - add Client :missing property testing testing testing
[2022-01-06T10:12:19.934] [ERROR] ma-core - add Client :missing property NaN post 1234
[2022-01-06T10:12:19.945] [ERROR] ma-core - Delete Error : Error
    at Context.<anonymous> (/home/azer/avaxia-monitpring-app/core-service/test/unit/client/delete/deleteClient.service.test.js:62:33)
    at callFn (/home/azer/avaxia-monitpring-app/core-service/node_modules/mocha/lib/runnable.js:366:21)
    at Test.Runnable.run (/home/azer/avaxia-monitpring-app/core-service/node_modules/mocha/lib/runnable.js:354:5)
    at Runner.runTest (/home/azer/avaxia-monitpring-app/core-service/node_modules/mocha/lib/runner.js:681:10)
    at /home/azer/avaxia-monitpring-app/core-service/node_modules/mocha/lib/runner.js:804:12
    at next (/home/azer/avaxia-monitpring-app/core-service/node_modules/mocha/lib/runner.js:596:14)
    at /home/azer/avaxia-monitpring-app/core-service/node_modules/mocha/lib/runner.js:606:7
    at next (/home/azer/avaxia-monitpring-app/core-service/node_modules/mocha/lib/runner.js:489:14)
    at cbHookRun (/home/azer/avaxia-monitpring-app/core-service/node_modules/mocha/lib/runner.js:554:7)
    at done (/home/azer/avaxia-monitpring-app/core-service/node_modules/mocha/lib/runnable.js:310:5)
    at callFn (/home/azer/avaxia-monitpring-app/core-service/node_modules/mocha/lib/runnable.js:389:7)
    at Hook.Runnable.run (/home/azer/avaxia-monitpring-app/core-service/node_modules/mocha/lib/runnable.js:354:5)
    at next (/home/azer/avaxia-monitpring-app/core-service/node_modules/mocha/lib/runner.js:513:10)
    at Immediate._onImmediate (/home/azer/avaxia-monitpring-app/core-service/node_modules/mocha/lib/runner.js:574:5)
    at processImmediate (internal/timers.js:464:21)
[2022-01-06T10:12:19.947] [ERROR] ma-core - Delete Error : Error: random error
    at Context.<anonymous> (/home/azer/avaxia-monitpring-app/core-service/test/unit/client/delete/deleteClient.service.test.js:72:33)
    at callFn (/home/azer/avaxia-monitpring-app/core-service/node_modules/mocha/lib/runnable.js:366:21)
    at Test.Runnable.run (/home/azer/avaxia-monitpring-app/core-service/node_modules/mocha/lib/runnable.js:354:5)
    at Runner.runTest (/home/azer/avaxia-monitpring-app/core-service/node_modules/mocha/lib/runner.js:681:10)
    at /home/azer/avaxia-monitpring-app/core-service/node_modules/mocha/lib/runner.js:804:12
    at next (/home/azer/avaxia-monitpring-app/core-service/node_modules/mocha/lib/runner.js:596:14)
    at /home/azer/avaxia-monitpring-app/core-service/node_modules/mocha/lib/runner.js:606:7
    at next (/home/azer/avaxia-monitpring-app/core-service/node_modules/mocha/lib/runner.js:489:14)
    at cbHookRun (/home/azer/avaxia-monitpring-app/core-service/node_modules/mocha/lib/runner.js:554:7)
    at done (/home/azer/avaxia-monitpring-app/core-service/node_modules/mocha/lib/runnable.js:310:5)
    at callFn (/home/azer/avaxia-monitpring-app/core-service/node_modules/mocha/lib/runnable.js:389:7)
    at Hook.Runnable.run (/home/azer/avaxia-monitpring-app/core-service/node_modules/mocha/lib/runnable.js:354:5)
    at next (/home/azer/avaxia-monitpring-app/core-service/node_modules/mocha/lib/runner.js:513:10)
    at Immediate._onImmediate (/home/azer/avaxia-monitpring-app/core-service/node_modules/mocha/lib/runner.js:574:5)
    at processImmediate (internal/timers.js:464:21)
[2022-01-06T10:12:19.970] [ERROR] ma-core - Get by System Error : Error: Random error
    at Context.<anonymous> (/home/azer/avaxia-monitpring-app/core-service/test/unit/client/getClientsBySystemId/getAllBySystemServiceTest.js:49:21)
    at callFn (/home/azer/avaxia-monitpring-app/core-service/node_modules/mocha/lib/runnable.js:366:21)
    at Test.Runnable.run (/home/azer/avaxia-monitpring-app/core-service/node_modules/mocha/lib/runnable.js:354:5)
    at Runner.runTest (/home/azer/avaxia-monitpring-app/core-service/node_modules/mocha/lib/runner.js:681:10)
    at /home/azer/avaxia-monitpring-app/core-service/node_modules/mocha/lib/runner.js:804:12
    at next (/home/azer/avaxia-monitpring-app/core-service/node_modules/mocha/lib/runner.js:596:14)
    at /home/azer/avaxia-monitpring-app/core-service/node_modules/mocha/lib/runner.js:606:7
    at next (/home/azer/avaxia-monitpring-app/core-service/node_modules/mocha/lib/runner.js:489:14)
    at cbHookRun (/home/azer/avaxia-monitpring-app/core-service/node_modules/mocha/lib/runner.js:554:7)
    at done (/home/azer/avaxia-monitpring-app/core-service/node_modules/mocha/lib/runnable.js:310:5)
    at callFn (/home/azer/avaxia-monitpring-app/core-service/node_modules/mocha/lib/runnable.js:389:7)
    at Hook.Runnable.run (/home/azer/avaxia-monitpring-app/core-service/node_modules/mocha/lib/runnable.js:354:5)
    at next (/home/azer/avaxia-monitpring-app/core-service/node_modules/mocha/lib/runner.js:513:10)
    at Immediate._onImmediate (/home/azer/avaxia-monitpring-app/core-service/node_modules/mocha/lib/runner.js:574:5)
    at processImmediate (internal/timers.js:464:21)
[2022-01-06T10:12:19.977] [ERROR] ma-core - Error
    at Context.<anonymous> (/home/azer/avaxia-monitpring-app/core-service/test/unit/client/update/updateClient.service.test.js:70:33)
    at callFn (/home/azer/avaxia-monitpring-app/core-service/node_modules/mocha/lib/runnable.js:366:21)
    at Test.Runnable.run (/home/azer/avaxia-monitpring-app/core-service/node_modules/mocha/lib/runnable.js:354:5)
    at Runner.runTest (/home/azer/avaxia-monitpring-app/core-service/node_modules/mocha/lib/runner.js:681:10)
    at /home/azer/avaxia-monitpring-app/core-service/node_modules/mocha/lib/runner.js:804:12
    at next (/home/azer/avaxia-monitpring-app/core-service/node_modules/mocha/lib/runner.js:596:14)
    at /home/azer/avaxia-monitpring-app/core-service/node_modules/mocha/lib/runner.js:606:7
    at next (/home/azer/avaxia-monitpring-app/core-service/node_modules/mocha/lib/runner.js:489:14)
    at cbHookRun (/home/azer/avaxia-monitpring-app/core-service/node_modules/mocha/lib/runner.js:554:7)
    at done (/home/azer/avaxia-monitpring-app/core-service/node_modules/mocha/lib/runnable.js:310:5)
    at callFn (/home/azer/avaxia-monitpring-app/core-service/node_modules/mocha/lib/runnable.js:389:7)
    at Hook.Runnable.run (/home/azer/avaxia-monitpring-app/core-service/node_modules/mocha/lib/runnable.js:354:5)
    at next (/home/azer/avaxia-monitpring-app/core-service/node_modules/mocha/lib/runner.js:513:10)
    at Immediate._onImmediate (/home/azer/avaxia-monitpring-app/core-service/node_modules/mocha/lib/runner.js:574:5)
    at processImmediate (internal/timers.js:464:21)
[2022-01-06T10:12:20.012] [ERROR] ma-core - Error: random error
    at Context.<anonymous> (/home/azer/avaxia-monitpring-app/core-service/test/unit/customer/getById/getByIdCustomer.service.test.js:88:24)
    at callFn (/home/azer/avaxia-monitpring-app/core-service/node_modules/mocha/lib/runnable.js:366:21)
    at Test.Runnable.run (/home/azer/avaxia-monitpring-app/core-service/node_modules/mocha/lib/runnable.js:354:5)
    at Runner.runTest (/home/azer/avaxia-monitpring-app/core-service/node_modules/mocha/lib/runner.js:681:10)
    at /home/azer/avaxia-monitpring-app/core-service/node_modules/mocha/lib/runner.js:804:12
    at next (/home/azer/avaxia-monitpring-app/core-service/node_modules/mocha/lib/runner.js:596:14)
    at /home/azer/avaxia-monitpring-app/core-service/node_modules/mocha/lib/runner.js:606:7
    at next (/home/azer/avaxia-monitpring-app/core-service/node_modules/mocha/lib/runner.js:489:14)
    at cbHookRun (/home/azer/avaxia-monitpring-app/core-service/node_modules/mocha/lib/runner.js:554:7)
    at done (/home/azer/avaxia-monitpring-app/core-service/node_modules/mocha/lib/runnable.js:310:5)
    at callFn (/home/azer/avaxia-monitpring-app/core-service/node_modules/mocha/lib/runnable.js:389:7)
    at Hook.Runnable.run (/home/azer/avaxia-monitpring-app/core-service/node_modules/mocha/lib/runnable.js:354:5)
    at next (/home/azer/avaxia-monitpring-app/core-service/node_modules/mocha/lib/runner.js:513:10)
    at Immediate._onImmediate (/home/azer/avaxia-monitpring-app/core-service/node_modules/mocha/lib/runner.js:574:5)
    at processImmediate (internal/timers.js:464:21)
[2022-01-06T10:12:20.023] [ERROR] ma-core - add customer fail :missing property testing testing testing
[2022-01-06T10:12:20.134] [ERROR] ma-core - Delete Error : Error
    at Context.<anonymous> (/home/azer/avaxia-monitpring-app/core-service/test/unit/host/delete/deleteHost.service.test.js:72:33)
    at callFn (/home/azer/avaxia-monitpring-app/core-service/node_modules/mocha/lib/runnable.js:366:21)
    at Test.Runnable.run (/home/azer/avaxia-monitpring-app/core-service/node_modules/mocha/lib/runnable.js:354:5)
    at Runner.runTest (/home/azer/avaxia-monitpring-app/core-service/node_modules/mocha/lib/runner.js:681:10)
    at /home/azer/avaxia-monitpring-app/core-service/node_modules/mocha/lib/runner.js:804:12
    at next (/home/azer/avaxia-monitpring-app/core-service/node_modules/mocha/lib/runner.js:596:14)
    at /home/azer/avaxia-monitpring-app/core-service/node_modules/mocha/lib/runner.js:606:7
    at next (/home/azer/avaxia-monitpring-app/core-service/node_modules/mocha/lib/runner.js:489:14)
    at cbHookRun (/home/azer/avaxia-monitpring-app/core-service/node_modules/mocha/lib/runner.js:554:7)
    at done (/home/azer/avaxia-monitpring-app/core-service/node_modules/mocha/lib/runnable.js:310:5)
    at callFn (/home/azer/avaxia-monitpring-app/core-service/node_modules/mocha/lib/runnable.js:389:7)
    at Hook.Runnable.run (/home/azer/avaxia-monitpring-app/core-service/node_modules/mocha/lib/runnable.js:354:5)
    at next (/home/azer/avaxia-monitpring-app/core-service/node_modules/mocha/lib/runner.js:513:10)
    at Immediate._onImmediate (/home/azer/avaxia-monitpring-app/core-service/node_modules/mocha/lib/runner.js:574:5)
    at processImmediate (internal/timers.js:464:21)
[2022-01-06T10:12:20.149] [ERROR] ma-core - Get by System Error : Error: Random error
    at Context.<anonymous> (/home/azer/avaxia-monitpring-app/core-service/test/unit/host/getAllBySystem/getAllBySystemServiceTest.js:49:21)
    at callFn (/home/azer/avaxia-monitpring-app/core-service/node_modules/mocha/lib/runnable.js:366:21)
    at Test.Runnable.run (/home/azer/avaxia-monitpring-app/core-service/node_modules/mocha/lib/runnable.js:354:5)
    at Runner.runTest (/home/azer/avaxia-monitpring-app/core-service/node_modules/mocha/lib/runner.js:681:10)
    at /home/azer/avaxia-monitpring-app/core-service/node_modules/mocha/lib/runner.js:804:12
    at next (/home/azer/avaxia-monitpring-app/core-service/node_modules/mocha/lib/runner.js:596:14)
    at /home/azer/avaxia-monitpring-app/core-service/node_modules/mocha/lib/runner.js:606:7
    at next (/home/azer/avaxia-monitpring-app/core-service/node_modules/mocha/lib/runner.js:489:14)
    at cbHookRun (/home/azer/avaxia-monitpring-app/core-service/node_modules/mocha/lib/runner.js:554:7)
    at done (/home/azer/avaxia-monitpring-app/core-service/node_modules/mocha/lib/runnable.js:310:5)
    at callFn (/home/azer/avaxia-monitpring-app/core-service/node_modules/mocha/lib/runnable.js:389:7)
    at Hook.Runnable.run (/home/azer/avaxia-monitpring-app/core-service/node_modules/mocha/lib/runnable.js:354:5)
    at next (/home/azer/avaxia-monitpring-app/core-service/node_modules/mocha/lib/runner.js:513:10)
    at Immediate._onImmediate (/home/azer/avaxia-monitpring-app/core-service/node_modules/mocha/lib/runner.js:574:5)
    at processImmediate (internal/timers.js:464:21)
[2022-01-06T10:12:20.157] [ERROR] ma-core - Get by ID Error : Error: random error
    at Context.<anonymous> (/home/azer/avaxia-monitpring-app/core-service/test/unit/host/getById/getByIdHost.service.test.js:58:24)
    at callFn (/home/azer/avaxia-monitpring-app/core-service/node_modules/mocha/lib/runnable.js:366:21)
    at Test.Runnable.run (/home/azer/avaxia-monitpring-app/core-service/node_modules/mocha/lib/runnable.js:354:5)
    at Runner.runTest (/home/azer/avaxia-monitpring-app/core-service/node_modules/mocha/lib/runner.js:681:10)
    at /home/azer/avaxia-monitpring-app/core-service/node_modules/mocha/lib/runner.js:804:12
    at next (/home/azer/avaxia-monitpring-app/core-service/node_modules/mocha/lib/runner.js:596:14)
    at /home/azer/avaxia-monitpring-app/core-service/node_modules/mocha/lib/runner.js:606:7
    at next (/home/azer/avaxia-monitpring-app/core-service/node_modules/mocha/lib/runner.js:489:14)
    at cbHookRun (/home/azer/avaxia-monitpring-app/core-service/node_modules/mocha/lib/runner.js:554:7)
    at done (/home/azer/avaxia-monitpring-app/core-service/node_modules/mocha/lib/runnable.js:310:5)
    at callFn (/home/azer/avaxia-monitpring-app/core-service/node_modules/mocha/lib/runnable.js:389:7)
    at Hook.Runnable.run (/home/azer/avaxia-monitpring-app/core-service/node_modules/mocha/lib/runnable.js:354:5)
    at next (/home/azer/avaxia-monitpring-app/core-service/node_modules/mocha/lib/runner.js:513:10)
    at Immediate._onImmediate (/home/azer/avaxia-monitpring-app/core-service/node_modules/mocha/lib/runner.js:574:5)
    at processImmediate (internal/timers.js:464:21)
[2022-01-06T10:12:20.163] [ERROR] ma-core - expected findOneAndUpdate to have been called exactly once, but it was called 0 times
[2022-01-06T10:12:20.172] [ERROR] ma-core - Update Error : Error
    at Context.<anonymous> (/home/azer/avaxia-monitpring-app/core-service/test/unit/host/update/updateHost.service.test.js:79:33)
    at callFn (/home/azer/avaxia-monitpring-app/core-service/node_modules/mocha/lib/runnable.js:366:21)
    at Test.Runnable.run (/home/azer/avaxia-monitpring-app/core-service/node_modules/mocha/lib/runnable.js:354:5)
    at Runner.runTest (/home/azer/avaxia-monitpring-app/core-service/node_modules/mocha/lib/runner.js:681:10)
    at /home/azer/avaxia-monitpring-app/core-service/node_modules/mocha/lib/runner.js:804:12
    at next (/home/azer/avaxia-monitpring-app/core-service/node_modules/mocha/lib/runner.js:596:14)
    at /home/azer/avaxia-monitpring-app/core-service/node_modules/mocha/lib/runner.js:606:7
    at next (/home/azer/avaxia-monitpring-app/core-service/node_modules/mocha/lib/runner.js:489:14)
    at cbHookRun (/home/azer/avaxia-monitpring-app/core-service/node_modules/mocha/lib/runner.js:554:7)
    at done (/home/azer/avaxia-monitpring-app/core-service/node_modules/mocha/lib/runnable.js:310:5)
    at callFn (/home/azer/avaxia-monitpring-app/core-service/node_modules/mocha/lib/runnable.js:389:7)
    at Hook.Runnable.run (/home/azer/avaxia-monitpring-app/core-service/node_modules/mocha/lib/runnable.js:354:5)
    at next (/home/azer/avaxia-monitpring-app/core-service/node_modules/mocha/lib/runner.js:513:10)
    at Immediate._onImmediate (/home/azer/avaxia-monitpring-app/core-service/node_modules/mocha/lib/runner.js:574:5)
    at processImmediate (internal/timers.js:464:21)
[2022-01-06T10:12:17.952] [ERROR] ma-core - cancel ItOperation :itOperation not found testing testing testing
[2022-01-06T10:12:17.954] [ERROR] ma-core - finish ItOperation :itOperation not found testing testing testing
[2022-01-06T10:12:20.197] [ERROR] ma-core - Error occur while Getting ItOperation By System Id : Error: Random error
    at Context.<anonymous> (/home/azer/avaxia-monitpring-app/core-service/test/unit/itOperation/getAllBySystem/getAllBySystemServiceTest.js:50:21)
    at callFn (/home/azer/avaxia-monitpring-app/core-service/node_modules/mocha/lib/runnable.js:366:21)
    at Test.Runnable.run (/home/azer/avaxia-monitpring-app/core-service/node_modules/mocha/lib/runnable.js:354:5)
    at Runner.runTest (/home/azer/avaxia-monitpring-app/core-service/node_modules/mocha/lib/runner.js:681:10)
    at /home/azer/avaxia-monitpring-app/core-service/node_modules/mocha/lib/runner.js:804:12
    at next (/home/azer/avaxia-monitpring-app/core-service/node_modules/mocha/lib/runner.js:596:14)
    at /home/azer/avaxia-monitpring-app/core-service/node_modules/mocha/lib/runner.js:606:7
    at next (/home/azer/avaxia-monitpring-app/core-service/node_modules/mocha/lib/runner.js:489:14)
    at cbHookRun (/home/azer/avaxia-monitpring-app/core-service/node_modules/mocha/lib/runner.js:554:7)
    at done (/home/azer/avaxia-monitpring-app/core-service/node_modules/mocha/lib/runnable.js:310:5)
    at callFn (/home/azer/avaxia-monitpring-app/core-service/node_modules/mocha/lib/runnable.js:389:7)
    at Hook.Runnable.run (/home/azer/avaxia-monitpring-app/core-service/node_modules/mocha/lib/runnable.js:354:5)
    at next (/home/azer/avaxia-monitpring-app/core-service/node_modules/mocha/lib/runner.js:513:10)
    at Immediate._onImmediate (/home/azer/avaxia-monitpring-app/core-service/node_modules/mocha/lib/runner.js:574:5)
    at processImmediate (internal/timers.js:464:21)
[2022-01-06T10:12:20.207] [ERROR] ma-core - add ItOperation fail :missing property testing testing testing
[2022-01-06T10:12:17.970] [ERROR] ma-core - remind ItOperation :itOperation not found testing testing testing
[2022-01-06T10:12:17.971] [ERROR] ma-core - send changes ItOperation :itOperation not found testing testing testing
[2022-01-06T10:12:20.223] [ERROR] ma-core - update ItOperation :itOperation not found testing testing testing
[2022-01-06T10:12:20.252] [ERROR] ma-core - delete Licence :licence not found testing testing testing
[2022-01-06T10:12:20.254] [ERROR] ma-core - delete Licence :licence not found NaN post 1234
[2022-01-06T10:12:20.263] [ERROR] ma-core - get licence By Id :Missing Customer ID NaN post 1234
[2022-01-06T10:12:20.264] [ERROR] ma-core - get licence By Id :Missing Customer ID testing testing testing
[2022-01-06T10:12:20.266] [ERROR] ma-core - get licence By Id :licence not found testing testing testing
[2022-01-06T10:12:20.268] [ERROR] ma-core - get licence By Id :licence not found NaN post 1234
[2022-01-06T10:12:20.273] [ERROR] ma-core - Error occur while Getting Licence By Customer Id : Error: random error
    at Context.<anonymous> (/home/azer/avaxia-monitpring-app/core-service/test/unit/licence/getActiveLicence/getActiveLIcenceServiceTest.js:52:17)
    at callFn (/home/azer/avaxia-monitpring-app/core-service/node_modules/mocha/lib/runnable.js:366:21)
    at Test.Runnable.run (/home/azer/avaxia-monitpring-app/core-service/node_modules/mocha/lib/runnable.js:354:5)
    at Runner.runTest (/home/azer/avaxia-monitpring-app/core-service/node_modules/mocha/lib/runner.js:681:10)
    at /home/azer/avaxia-monitpring-app/core-service/node_modules/mocha/lib/runner.js:804:12
    at next (/home/azer/avaxia-monitpring-app/core-service/node_modules/mocha/lib/runner.js:596:14)
    at /home/azer/avaxia-monitpring-app/core-service/node_modules/mocha/lib/runner.js:606:7
    at next (/home/azer/avaxia-monitpring-app/core-service/node_modules/mocha/lib/runner.js:489:14)
    at cbHookRun (/home/azer/avaxia-monitpring-app/core-service/node_modules/mocha/lib/runner.js:554:7)
    at done (/home/azer/avaxia-monitpring-app/core-service/node_modules/mocha/lib/runnable.js:310:5)
    at callFn (/home/azer/avaxia-monitpring-app/core-service/node_modules/mocha/lib/runnable.js:389:7)
    at Hook.Runnable.run (/home/azer/avaxia-monitpring-app/core-service/node_modules/mocha/lib/runnable.js:354:5)
    at next (/home/azer/avaxia-monitpring-app/core-service/node_modules/mocha/lib/runner.js:513:10)
    at Immediate._onImmediate (/home/azer/avaxia-monitpring-app/core-service/node_modules/mocha/lib/runner.js:574:5)
    at processImmediate (internal/timers.js:464:21)
[2022-01-06T10:12:20.277] [ERROR] ma-core - Error occur while Getting Licence By Customer Id : Error: random error
    at Context.<anonymous> (/home/azer/avaxia-monitpring-app/core-service/test/unit/licence/getByCustomer/getByCustomerLicence.service.test.js:61:17)
    at callFn (/home/azer/avaxia-monitpring-app/core-service/node_modules/mocha/lib/runnable.js:366:21)
    at Test.Runnable.run (/home/azer/avaxia-monitpring-app/core-service/node_modules/mocha/lib/runnable.js:354:5)
    at Runner.runTest (/home/azer/avaxia-monitpring-app/core-service/node_modules/mocha/lib/runner.js:681:10)
    at /home/azer/avaxia-monitpring-app/core-service/node_modules/mocha/lib/runner.js:804:12
    at next (/home/azer/avaxia-monitpring-app/core-service/node_modules/mocha/lib/runner.js:596:14)
    at /home/azer/avaxia-monitpring-app/core-service/node_modules/mocha/lib/runner.js:606:7
    at next (/home/azer/avaxia-monitpring-app/core-service/node_modules/mocha/lib/runner.js:489:14)
    at cbHookRun (/home/azer/avaxia-monitpring-app/core-service/node_modules/mocha/lib/runner.js:554:7)
    at done (/home/azer/avaxia-monitpring-app/core-service/node_modules/mocha/lib/runnable.js:310:5)
    at callFn (/home/azer/avaxia-monitpring-app/core-service/node_modules/mocha/lib/runnable.js:389:7)
    at Hook.Runnable.run (/home/azer/avaxia-monitpring-app/core-service/node_modules/mocha/lib/runnable.js:354:5)
    at next (/home/azer/avaxia-monitpring-app/core-service/node_modules/mocha/lib/runner.js:513:10)
    at Immediate._onImmediate (/home/azer/avaxia-monitpring-app/core-service/node_modules/mocha/lib/runner.js:574:5)
    at processImmediate (internal/timers.js:464:21)
[2022-01-06T10:12:20.285] [ERROR] ma-core - get licence By Id :licence not found testing testing testing
[2022-01-06T10:12:20.287] [ERROR] ma-core - get licence By Id :licence not found NaN post 1234
[2022-01-06T10:12:20.298] [ERROR] ma-core - add Licence :missing property testing testing testing
[2022-01-06T10:12:20.300] [ERROR] ma-core - add Licence :missing property NaN post 1234
[2022-01-06T10:12:20.313] [ERROR] ma-core - update licence By Customer :licence not found testing testing testing
[2022-01-06T10:12:20.314] [ERROR] ma-core - update licence By Customer :licence not found NaN post 1234
[2022-01-06T10:12:20.331] [ERROR] ma-core - delete Map By Id :MAP not found testing testing testing
[2022-01-06T10:12:20.334] [ERROR] ma-core - delete Map By Id :missing ID testing testing testing
[2022-01-06T10:12:20.336] [ERROR] ma-core - delete Map By Id :missing ID testing testing testing
[2022-01-06T10:12:20.338] [ERROR] ma-core - delete Map By Id :missing ID NaN post 1234
[2022-01-06T10:12:20.358] [ERROR] ma-core - Get by System Error : Error: Random error
    at Context.<anonymous> (/home/azer/avaxia-monitpring-app/core-service/test/unit/map/getAllBySystem/getAllBySystemServiceTest.js:98:21)
    at callFn (/home/azer/avaxia-monitpring-app/core-service/node_modules/mocha/lib/runnable.js:366:21)
    at Test.Runnable.run (/home/azer/avaxia-monitpring-app/core-service/node_modules/mocha/lib/runnable.js:354:5)
    at Runner.runTest (/home/azer/avaxia-monitpring-app/core-service/node_modules/mocha/lib/runner.js:681:10)
    at /home/azer/avaxia-monitpring-app/core-service/node_modules/mocha/lib/runner.js:804:12
    at next (/home/azer/avaxia-monitpring-app/core-service/node_modules/mocha/lib/runner.js:596:14)
    at /home/azer/avaxia-monitpring-app/core-service/node_modules/mocha/lib/runner.js:606:7
    at next (/home/azer/avaxia-monitpring-app/core-service/node_modules/mocha/lib/runner.js:489:14)
    at cbHookRun (/home/azer/avaxia-monitpring-app/core-service/node_modules/mocha/lib/runner.js:554:7)
    at done (/home/azer/avaxia-monitpring-app/core-service/node_modules/mocha/lib/runnable.js:310:5)
    at callFn (/home/azer/avaxia-monitpring-app/core-service/node_modules/mocha/lib/runnable.js:389:7)
    at Hook.Runnable.run (/home/azer/avaxia-monitpring-app/core-service/node_modules/mocha/lib/runnable.js:354:5)
    at next (/home/azer/avaxia-monitpring-app/core-service/node_modules/mocha/lib/runner.js:513:10)
    at Immediate._onImmediate (/home/azer/avaxia-monitpring-app/core-service/node_modules/mocha/lib/runner.js:574:5)
    at processImmediate (internal/timers.js:464:21)
[2022-01-06T10:12:20.390] [ERROR] ma-core - delete Module :module not found testing testing testing
[2022-01-06T10:12:20.391] [ERROR] ma-core - delete Module :module not found NaN post 1234
[2022-01-06T10:12:20.394] [ERROR] ma-core - delete Module :missing ID testing testing testing
[2022-01-06T10:12:20.395] [ERROR] ma-core - delete Module :missing ID testing testing testing
[2022-01-06T10:12:20.404] [ERROR] ma-core - get All Basic Module :missing property testing testing testing
[2022-01-06T10:12:20.406] [ERROR] ma-core - get All Basic Module :missing property NaN post 1234
[2022-01-06T10:12:20.411] [ERROR] ma-core - get All Module :missing property testing testing testing
[2022-01-06T10:12:20.413] [ERROR] ma-core - get All Module :missing property NaN post 1234
[2022-01-06T10:12:20.420] [ERROR] ma-core - get module By Id :module not found testing testing testing
[2022-01-06T10:12:20.421] [ERROR] ma-core - get module By Id :module not found testing testing testing
[2022-01-06T10:12:20.424] [ERROR] ma-core - get module By Id :module not found NaN post 1234
[2022-01-06T10:12:20.435] [ERROR] ma-core - add Module :missing property testing testing testing
[2022-01-06T10:12:20.437] [ERROR] ma-core - add Module :missing property NaN post 1234
[2022-01-06T10:12:20.446] [ERROR] ma-core - update module By Customer :module not found testing testing testing
[2022-01-06T10:12:20.447] [ERROR] ma-core - update module By Customer :module not found testing testing testing
[2022-01-06T10:12:20.450] [ERROR] ma-core - update module By Customer :module not found NaN post 1234
[2022-01-06T10:12:20.526] [ERROR] ma-core - get All nomenclature :get All nomenclature : testing testing testing
[2022-01-06T10:12:20.528] [ERROR] ma-core - get All nomenclature :get All nomenclature : NaN post 1234
[2022-01-06T10:12:20.540] [ERROR] ma-core - get one result error testing testing testing
[2022-01-06T10:12:20.542] [ERROR] ma-core - get one result error testing testing testing
[2022-01-06T10:12:20.548] [ERROR] ma-core - get Previous result error testing testing testing
[2022-01-06T10:12:20.569] [ERROR] ma-core - delete Result Form :task not found testing testing testing
[2022-01-06T10:12:20.571] [ERROR] ma-core - delete Result Form :task not found NaN post 1234
[2022-01-06T10:12:20.586] [ERROR] ma-core - get All result form :missing property testing testing testing
[2022-01-06T10:12:20.588] [ERROR] ma-core - get All result form :missing property NaN post 1234
[2022-01-06T10:12:20.596] [ERROR] ma-core - get by id Result Form :task not found testing testing testing
[2022-01-06T10:12:20.597] [ERROR] ma-core - get by id Result Form :task not found NaN post 1234
[2022-01-06T10:12:20.607] [ERROR] ma-core - add result form :missing property testing testing testing
[2022-01-06T10:12:20.608] [ERROR] ma-core - add result form :missing property NaN post 1234
[2022-01-06T10:12:20.615] [ERROR] ma-core - update Result Form  :task not found testing testing testing
[2022-01-06T10:12:20.616] [ERROR] ma-core - update Result Form  :task not found NaN post 1234
[2022-01-06T10:12:20.626] [ERROR] ma-core - delete Role :role not found testing testing testing
[2022-01-06T10:12:20.628] [ERROR] ma-core - delete Role :role not found NaN post 1234
[2022-01-06T10:12:20.629] [ERROR] ma-core - delete Role :missing ID testing testing testing
[2022-01-06T10:12:20.631] [ERROR] ma-core - delete Role :missing ID testing testing testing
[2022-01-06T10:12:20.643] [ERROR] ma-core - get All Role :missing property testing testing testing
[2022-01-06T10:12:20.646] [ERROR] ma-core - get All Role :missing property NaN post 1234
[2022-01-06T10:12:20.656] [ERROR] ma-core - get by id Role :role not found testing testing testing
[2022-01-06T10:12:20.658] [ERROR] ma-core - get by id Role :role not found testing testing testing
[2022-01-06T10:12:20.660] [ERROR] ma-core - get by id Role :role not found NaN post 1234
[2022-01-06T10:12:20.673] [ERROR] ma-core - get by user Role :user not found testing testing testing
[2022-01-06T10:12:20.674] [ERROR] ma-core - get by user Role :role not found testing testing testing
[2022-01-06T10:12:20.677] [ERROR] ma-core - get by user Role :role not found NaN get 1234
[2022-01-06T10:12:20.680] [ERROR] ma-core - add Role :missing property testing testing testing
[2022-01-06T10:12:20.683] [ERROR] ma-core - add Role :missing property NaN post 1234
[2022-01-06T10:12:20.696] [ERROR] ma-core - update Role :role not found testing testing testing
[2022-01-06T10:12:20.698] [ERROR] ma-core - update Role :role not found testing testing testing
[2022-01-06T10:12:20.700] [ERROR] ma-core - update Role :role not found NaN post 1234
[2022-01-06T10:12:20.709] [ERROR] ma-core - add Client :missing property testing testing testing
[2022-01-06T10:12:20.710] [ERROR] ma-core - add Client :missing property NaN post 1234
[2022-01-06T10:12:20.737] [ERROR] ma-core - 
[2022-01-06T10:12:20.798] [ERROR] ma-core - delete Sla :sla not found testing testing testing
[2022-01-06T10:12:20.799] [ERROR] ma-core - delete Sla :sla not found testing testing testing
[2022-01-06T10:12:20.801] [ERROR] ma-core - delete Sla :sla not found NaN post 1234
[2022-01-06T10:12:20.810] [ERROR] ma-core - get sla By Id :sla not found testing testing testing
[2022-01-06T10:12:20.813] [ERROR] ma-core - get sla By Id :sla not found testing testing testing
[2022-01-06T10:12:20.814] [ERROR] ma-core - get sla By Id :sla not found NaN post 1234
[2022-01-06T10:12:20.823] [ERROR] ma-core - Error occur while Getting Sla By slaContract Id : Error: Random error
    at Context.<anonymous> (/home/azer/avaxia-monitpring-app/core-service/test/unit/sla/getByslaContract/getslaBySlaContract.service.test.js:70:21)
    at callFn (/home/azer/avaxia-monitpring-app/core-service/node_modules/mocha/lib/runnable.js:366:21)
    at Test.Runnable.run (/home/azer/avaxia-monitpring-app/core-service/node_modules/mocha/lib/runnable.js:354:5)
    at Runner.runTest (/home/azer/avaxia-monitpring-app/core-service/node_modules/mocha/lib/runner.js:681:10)
    at /home/azer/avaxia-monitpring-app/core-service/node_modules/mocha/lib/runner.js:804:12
    at next (/home/azer/avaxia-monitpring-app/core-service/node_modules/mocha/lib/runner.js:596:14)
    at /home/azer/avaxia-monitpring-app/core-service/node_modules/mocha/lib/runner.js:606:7
    at next (/home/azer/avaxia-monitpring-app/core-service/node_modules/mocha/lib/runner.js:489:14)
    at cbHookRun (/home/azer/avaxia-monitpring-app/core-service/node_modules/mocha/lib/runner.js:554:7)
    at done (/home/azer/avaxia-monitpring-app/core-service/node_modules/mocha/lib/runnable.js:310:5)
    at callFn (/home/azer/avaxia-monitpring-app/core-service/node_modules/mocha/lib/runnable.js:389:7)
    at Hook.Runnable.run (/home/azer/avaxia-monitpring-app/core-service/node_modules/mocha/lib/runnable.js:354:5)
    at next (/home/azer/avaxia-monitpring-app/core-service/node_modules/mocha/lib/runner.js:513:10)
    at Immediate._onImmediate (/home/azer/avaxia-monitpring-app/core-service/node_modules/mocha/lib/runner.js:574:5)
    at processImmediate (internal/timers.js:464:21)
[2022-01-06T10:12:20.832] [ERROR] ma-core - add Sla :missing property testing testing testing
[2022-01-06T10:12:20.835] [ERROR] ma-core - add Sla :missing property NaN post 1234
[2022-01-06T10:12:20.853] [ERROR] ma-core - update sla By SlaContract :sla not found testing testing testing
[2022-01-06T10:12:20.854] [ERROR] ma-core - update sla By SlaContract :sla not found testing testing testing
[2022-01-06T10:12:20.858] [ERROR] ma-core - update sla By SlaContract :sla not found NaN post 1234
[2022-01-06T10:12:20.869] [ERROR] ma-core - delete SlaContract :slaContract not found testing testing testing
[2022-01-06T10:12:20.870] [ERROR] ma-core - delete SlaContract :slaContract not found NaN post 1234
[2022-01-06T10:12:20.884] [ERROR] ma-core - Get by Customer Error : Error: Random error
    at Context.<anonymous> (/home/azer/avaxia-monitpring-app/core-service/test/unit/slaContract/getAllSlaContractByCustomerId/getAllSlaContractByCustomerIdServiceTest.js:78:21)
    at callFn (/home/azer/avaxia-monitpring-app/core-service/node_modules/mocha/lib/runnable.js:366:21)
    at Test.Runnable.run (/home/azer/avaxia-monitpring-app/core-service/node_modules/mocha/lib/runnable.js:354:5)
    at Runner.runTest (/home/azer/avaxia-monitpring-app/core-service/node_modules/mocha/lib/runner.js:681:10)
    at /home/azer/avaxia-monitpring-app/core-service/node_modules/mocha/lib/runner.js:804:12
    at next (/home/azer/avaxia-monitpring-app/core-service/node_modules/mocha/lib/runner.js:596:14)
    at /home/azer/avaxia-monitpring-app/core-service/node_modules/mocha/lib/runner.js:606:7
    at next (/home/azer/avaxia-monitpring-app/core-service/node_modules/mocha/lib/runner.js:489:14)
    at cbHookRun (/home/azer/avaxia-monitpring-app/core-service/node_modules/mocha/lib/runner.js:554:7)
    at done (/home/azer/avaxia-monitpring-app/core-service/node_modules/mocha/lib/runnable.js:310:5)
    at callFn (/home/azer/avaxia-monitpring-app/core-service/node_modules/mocha/lib/runnable.js:389:7)
    at Hook.Runnable.run (/home/azer/avaxia-monitpring-app/core-service/node_modules/mocha/lib/runnable.js:354:5)
    at next (/home/azer/avaxia-monitpring-app/core-service/node_modules/mocha/lib/runner.js:513:10)
    at Immediate._onImmediate (/home/azer/avaxia-monitpring-app/core-service/node_modules/mocha/lib/runner.js:574:5)
    at processImmediate (internal/timers.js:464:21)
[2022-01-06T10:12:20.889] [ERROR] ma-core - get slaContract By Customer :customer not found testing testing testing
[2022-01-06T10:12:20.890] [ERROR] ma-core - get slaContract By Customer :customer not found NaN post 1234
[2022-01-06T10:12:20.895] [ERROR] ma-core - get slaContract By Id :slaContract not found testing testing testing
[2022-01-06T10:12:20.897] [ERROR] ma-core - get slaContract By Id :slaContract not found NaN post 1234
[2022-01-06T10:12:20.906] [ERROR] ma-core - add SlaContract :missing property testing testing testing
[2022-01-06T10:12:20.907] [ERROR] ma-core - add SlaContract :missing property NaN post 1234
[2022-01-06T10:12:20.919] [ERROR] ma-core - update slaContract By Customer :slaContract not found testing testing testing
[2022-01-06T10:12:20.921] [ERROR] ma-core - update slaContract By Customer :slaContract not found NaN post 1234
[2022-01-06T10:12:21.016] [ERROR] ma-core - Get by Customer Error : Error: Random error
    at Context.<anonymous> (/home/azer/avaxia-monitpring-app/core-service/test/unit/system/getAllSystemByCustomerId/getAllSystemByCustomerIdServiceTest.js:52:21)
    at callFn (/home/azer/avaxia-monitpring-app/core-service/node_modules/mocha/lib/runnable.js:366:21)
    at Test.Runnable.run (/home/azer/avaxia-monitpring-app/core-service/node_modules/mocha/lib/runnable.js:354:5)
    at Runner.runTest (/home/azer/avaxia-monitpring-app/core-service/node_modules/mocha/lib/runner.js:681:10)
    at /home/azer/avaxia-monitpring-app/core-service/node_modules/mocha/lib/runner.js:804:12
    at next (/home/azer/avaxia-monitpring-app/core-service/node_modules/mocha/lib/runner.js:596:14)
    at /home/azer/avaxia-monitpring-app/core-service/node_modules/mocha/lib/runner.js:606:7
    at next (/home/azer/avaxia-monitpring-app/core-service/node_modules/mocha/lib/runner.js:489:14)
    at cbHookRun (/home/azer/avaxia-monitpring-app/core-service/node_modules/mocha/lib/runner.js:554:7)
    at done (/home/azer/avaxia-monitpring-app/core-service/node_modules/mocha/lib/runnable.js:310:5)
    at callFn (/home/azer/avaxia-monitpring-app/core-service/node_modules/mocha/lib/runnable.js:389:7)
    at Hook.Runnable.run (/home/azer/avaxia-monitpring-app/core-service/node_modules/mocha/lib/runnable.js:354:5)
    at next (/home/azer/avaxia-monitpring-app/core-service/node_modules/mocha/lib/runner.js:513:10)
    at Immediate._onImmediate (/home/azer/avaxia-monitpring-app/core-service/node_modules/mocha/lib/runner.js:574:5)
    at processImmediate (internal/timers.js:464:21)
[2022-01-06T10:12:21.043] [ERROR] ma-core - Get Categories by Customer ID and Type ID Error : Error: Random error
    at Context.<anonymous> (/home/azer/avaxia-monitpring-app/core-service/test/unit/system/getCategoryByTypesByCustomer/getCategoryByTypesByCustomerServiceTest.js:122:21)
    at callFn (/home/azer/avaxia-monitpring-app/core-service/node_modules/mocha/lib/runnable.js:366:21)
    at Test.Runnable.run (/home/azer/avaxia-monitpring-app/core-service/node_modules/mocha/lib/runnable.js:354:5)
    at Runner.runTest (/home/azer/avaxia-monitpring-app/core-service/node_modules/mocha/lib/runner.js:681:10)
    at /home/azer/avaxia-monitpring-app/core-service/node_modules/mocha/lib/runner.js:804:12
    at next (/home/azer/avaxia-monitpring-app/core-service/node_modules/mocha/lib/runner.js:596:14)
    at /home/azer/avaxia-monitpring-app/core-service/node_modules/mocha/lib/runner.js:606:7
    at next (/home/azer/avaxia-monitpring-app/core-service/node_modules/mocha/lib/runner.js:489:14)
    at cbHookRun (/home/azer/avaxia-monitpring-app/core-service/node_modules/mocha/lib/runner.js:554:7)
    at done (/home/azer/avaxia-monitpring-app/core-service/node_modules/mocha/lib/runnable.js:310:5)
    at callFn (/home/azer/avaxia-monitpring-app/core-service/node_modules/mocha/lib/runnable.js:389:7)
    at Hook.Runnable.run (/home/azer/avaxia-monitpring-app/core-service/node_modules/mocha/lib/runnable.js:354:5)
    at next (/home/azer/avaxia-monitpring-app/core-service/node_modules/mocha/lib/runner.js:513:10)
    at Immediate._onImmediate (/home/azer/avaxia-monitpring-app/core-service/node_modules/mocha/lib/runner.js:574:5)
    at processImmediate (internal/timers.js:464:21)
[2022-01-06T10:12:21.067] [ERROR] ma-core - Get types by Customer ID Error : Error: Random error
    at Context.<anonymous> (/home/azer/avaxia-monitpring-app/core-service/test/unit/system/getTypeByCustomer/getTypesByCustomerServiceTest.js:122:21)
    at callFn (/home/azer/avaxia-monitpring-app/core-service/node_modules/mocha/lib/runnable.js:366:21)
    at Test.Runnable.run (/home/azer/avaxia-monitpring-app/core-service/node_modules/mocha/lib/runnable.js:354:5)
    at Runner.runTest (/home/azer/avaxia-monitpring-app/core-service/node_modules/mocha/lib/runner.js:681:10)
    at /home/azer/avaxia-monitpring-app/core-service/node_modules/mocha/lib/runner.js:804:12
    at next (/home/azer/avaxia-monitpring-app/core-service/node_modules/mocha/lib/runner.js:596:14)
    at /home/azer/avaxia-monitpring-app/core-service/node_modules/mocha/lib/runner.js:606:7
    at next (/home/azer/avaxia-monitpring-app/core-service/node_modules/mocha/lib/runner.js:489:14)
    at cbHookRun (/home/azer/avaxia-monitpring-app/core-service/node_modules/mocha/lib/runner.js:554:7)
    at done (/home/azer/avaxia-monitpring-app/core-service/node_modules/mocha/lib/runnable.js:310:5)
    at callFn (/home/azer/avaxia-monitpring-app/core-service/node_modules/mocha/lib/runnable.js:389:7)
    at Hook.Runnable.run (/home/azer/avaxia-monitpring-app/core-service/node_modules/mocha/lib/runnable.js:354:5)
    at next (/home/azer/avaxia-monitpring-app/core-service/node_modules/mocha/lib/runner.js:513:10)
    at Immediate._onImmediate (/home/azer/avaxia-monitpring-app/core-service/node_modules/mocha/lib/runner.js:574:5)
    at processImmediate (internal/timers.js:464:21)
[2022-01-06T10:12:21.089] [ERROR] ma-core - get All Task By filter error :error testing testing testing
[2022-01-06T10:12:21.096] [ERROR] ma-core - get by id Task :task not found testing testing testing
[2022-01-06T10:12:21.098] [ERROR] ma-core - get by id Task :task not found NaN post 1234
[2022-01-06T10:12:21.106] [ERROR] ma-core - get All Task By filter error :error testing testing testing
[2022-01-06T10:12:21.210] [ERROR] ma-core - get Created Tasks error : error testing testing testing
[2022-01-06T10:12:21.215] [ERROR] ma-core - get Created Tasks error : error NaN post 1234
[2022-01-06T10:12:21.230] [ERROR] ma-core - add Task :missing property testing testing testing
[2022-01-06T10:12:21.231] [ERROR] ma-core - add Task :missing property NaN post 1234
[2022-01-06T10:12:21.245] [ERROR] ma-core - add Many Task :missing property testing testing testing
[2022-01-06T10:12:21.247] [ERROR] ma-core - add Many Task :missing property NaN post 1234
[2022-01-06T10:12:21.260] [ERROR] ma-core - update Task :task not found testing testing testing
[2022-01-06T10:12:21.261] [ERROR] ma-core - update Task :task not found NaN post 1234
[2022-01-06T10:12:21.271] [ERROR] ma-core - Update Task Assignee :task not found testing testing testing
[2022-01-06T10:12:21.286] [ERROR] ma-core - Failed to Cancel the Task :failed to update the task testing testing testing
[2022-01-06T10:12:21.288] [ERROR] ma-core - Failed to Cancel the Task :failed to update the task NaN post 1234
[2022-01-06T10:12:21.296] [ERROR] ma-core - Failed to reject the Task :failed to update the task testing testing testing
[2022-01-06T10:12:21.297] [ERROR] ma-core - Failed to reject the Task :failed to update the task NaN post 1234
[2022-01-06T10:12:21.306] [ERROR] ma-core - Failed to delete the Task :failed to update the task testing testing testing
[2022-01-06T10:12:21.308] [ERROR] ma-core - Failed to delete the Task :failed to update the task NaN post 1234
[2022-01-06T10:12:21.316] [ERROR] ma-core - Failed to finish the Task :failed to update the task testing testing testing
[2022-01-06T10:12:21.318] [ERROR] ma-core - Failed to finish the Task :failed to update the task NaN post 1234
[2022-01-06T10:12:21.327] [ERROR] ma-core - Failed to reject the Task :failed to update the task testing testing testing
[2022-01-06T10:12:21.328] [ERROR] ma-core - Failed to reject the Task :failed to update the task NaN post 1234
[2022-01-06T10:12:21.331] [ERROR] ma-core - An unexpected error occurred during auto start task Error: WARNING: Date in past. Will never be fired.
    at CronTime.sendAt (/home/azer/avaxia-monitpring-app/core-service/node_modules/cron/lib/cron.js:148:12)
    at CronTime.getTimeout (/home/azer/avaxia-monitpring-app/core-service/node_modules/cron/lib/cron.js:175:29)
    at CronJob.start (/home/azer/avaxia-monitpring-app/core-service/node_modules/cron/lib/cron.js:613:31)
    at new CronJob (/home/azer/avaxia-monitpring-app/core-service/node_modules/cron/lib/cron.js:576:10)
    at module.exports (/home/azer/avaxia-monitpring-app/core-service/services/task/autoStartTaskCron.js:2:1041)
    at Object.exports.validateTask (/home/azer/avaxia-monitpring-app/core-service/controllers/task.controller.js:11:699)
    at async Context.<anonymous> (/home/azer/avaxia-monitpring-app/core-service/test/unit/task/updateState/validateTask.controller.test.js:51:5)
[2022-01-06T10:12:21.337] [ERROR] ma-core - An unexpected error occurred during auto start task Error: WARNING: Date in past. Will never be fired.
    at CronTime.sendAt (/home/azer/avaxia-monitpring-app/core-service/node_modules/cron/lib/cron.js:148:12)
    at CronTime.getTimeout (/home/azer/avaxia-monitpring-app/core-service/node_modules/cron/lib/cron.js:175:29)
    at CronJob.start (/home/azer/avaxia-monitpring-app/core-service/node_modules/cron/lib/cron.js:613:31)
    at new CronJob (/home/azer/avaxia-monitpring-app/core-service/node_modules/cron/lib/cron.js:576:10)
    at module.exports (/home/azer/avaxia-monitpring-app/core-service/services/task/autoStartTaskCron.js:2:1041)
    at Object.exports.validateTask (/home/azer/avaxia-monitpring-app/core-service/controllers/task.controller.js:11:699)
    at async Context.<anonymous> (/home/azer/avaxia-monitpring-app/core-service/test/unit/task/updateState/validateTask.controller.test.js:95:5)
[2022-01-06T10:12:21.344] [ERROR] ma-core - An unexpected error occurred during auto start task Error: WARNING: Date in past. Will never be fired.
    at CronTime.sendAt (/home/azer/avaxia-monitpring-app/core-service/node_modules/cron/lib/cron.js:148:12)
    at CronTime.getTimeout (/home/azer/avaxia-monitpring-app/core-service/node_modules/cron/lib/cron.js:175:29)
    at CronJob.start (/home/azer/avaxia-monitpring-app/core-service/node_modules/cron/lib/cron.js:613:31)
    at new CronJob (/home/azer/avaxia-monitpring-app/core-service/node_modules/cron/lib/cron.js:576:10)
    at module.exports (/home/azer/avaxia-monitpring-app/core-service/services/task/autoStartTaskCron.js:2:1041)
    at Object.exports.validateTask (/home/azer/avaxia-monitpring-app/core-service/controllers/task.controller.js:11:699)
    at async Context.<anonymous> (/home/azer/avaxia-monitpring-app/core-service/test/unit/task/updateState/validateTask.controller.test.js:176:5)
[2022-01-06T10:12:21.344] [ERROR] ma-core - Failed to validate the Task :failed to update the task testing testing testing
[2022-01-06T10:12:21.349] [ERROR] ma-core - An unexpected error occurred during auto start task Error: WARNING: Date in past. Will never be fired.
    at CronTime.sendAt (/home/azer/avaxia-monitpring-app/core-service/node_modules/cron/lib/cron.js:148:12)
    at CronTime.getTimeout (/home/azer/avaxia-monitpring-app/core-service/node_modules/cron/lib/cron.js:175:29)
    at CronJob.start (/home/azer/avaxia-monitpring-app/core-service/node_modules/cron/lib/cron.js:613:31)
    at new CronJob (/home/azer/avaxia-monitpring-app/core-service/node_modules/cron/lib/cron.js:576:10)
    at module.exports (/home/azer/avaxia-monitpring-app/core-service/services/task/autoStartTaskCron.js:2:1041)
    at Object.exports.validateTask (/home/azer/avaxia-monitpring-app/core-service/controllers/task.controller.js:11:699)
    at async Context.<anonymous> (/home/azer/avaxia-monitpring-app/core-service/test/unit/task/updateState/validateTask.controller.test.js:219:5)
[2022-01-06T10:12:21.350] [ERROR] ma-core - Failed to validate the Task :failed to update the task NaN post 1234
[2022-01-06T10:12:21.361] [ERROR] ma-core - update Task :You are not authorized to perform this action testing testing testing
[2022-01-06T10:12:21.364] [ERROR] ma-core - update Task :task not found NaN post 1234
[2022-01-06T10:12:21.429] [ERROR] ma-core - random Error
[2022-01-06T10:12:22.084] [ERROR] ma-core - random error
[2022-01-06T10:22:12.718] [ERROR] ma-core - get All Task By filter error :error testing testing testing
[2022-01-06T10:22:12.727] [ERROR] ma-core - get by id Task :task not found testing testing testing
[2022-01-06T10:22:12.729] [ERROR] ma-core - get by id Task :task not found NaN post 1234
[2022-01-06T10:22:12.739] [ERROR] ma-core - get All Task By filter error :error testing testing testing
[2022-01-06T10:22:12.841] [ERROR] ma-core - get Created Tasks error : error testing testing testing
[2022-01-06T10:22:12.846] [ERROR] ma-core - get Created Tasks error : error NaN post 1234
[2022-01-06T10:22:12.859] [ERROR] ma-core - add Task :missing property testing testing testing
[2022-01-06T10:22:12.860] [ERROR] ma-core - add Task :missing property NaN post 1234
[2022-01-06T10:22:12.874] [ERROR] ma-core - add Many Task :missing property testing testing testing
[2022-01-06T10:22:12.876] [ERROR] ma-core - add Many Task :missing property NaN post 1234
[2022-01-06T10:22:12.894] [ERROR] ma-core - update Task :task not found testing testing testing
[2022-01-06T10:22:12.895] [ERROR] ma-core - update Task :task not found NaN post 1234
[2022-01-06T10:22:12.897] [ERROR] ma-core - Socket.io is not initialized !
[2022-01-06T10:22:12.905] [ERROR] ma-core - Update Task Assignee :task not found testing testing testing
[2022-01-06T10:22:12.922] [ERROR] ma-core - Failed to Cancel the Task :failed to update the task testing testing testing
[2022-01-06T10:22:12.924] [ERROR] ma-core - Failed to Cancel the Task :failed to update the task NaN post 1234
[2022-01-06T10:22:12.932] [ERROR] ma-core - Failed to reject the Task :failed to update the task testing testing testing
[2022-01-06T10:22:12.934] [ERROR] ma-core - Failed to reject the Task :failed to update the task NaN post 1234
[2022-01-06T10:22:12.943] [ERROR] ma-core - Failed to delete the Task :failed to update the task testing testing testing
[2022-01-06T10:22:12.945] [ERROR] ma-core - Failed to delete the Task :failed to update the task NaN post 1234
[2022-01-06T10:22:12.953] [ERROR] ma-core - Failed to finish the Task :failed to update the task testing testing testing
[2022-01-06T10:22:12.954] [ERROR] ma-core - Failed to finish the Task :failed to update the task NaN post 1234
[2022-01-06T10:22:12.963] [ERROR] ma-core - Failed to reject the Task :failed to update the task testing testing testing
[2022-01-06T10:22:12.965] [ERROR] ma-core - Failed to reject the Task :failed to update the task NaN post 1234
[2022-01-06T10:22:12.971] [ERROR] ma-core - An unexpected error occurred during auto start task Error: WARNING: Date in past. Will never be fired.
    at CronTime.sendAt (/home/azer/avaxia-monitpring-app/core-service/node_modules/cron/lib/cron.js:148:12)
    at CronTime.getTimeout (/home/azer/avaxia-monitpring-app/core-service/node_modules/cron/lib/cron.js:175:29)
    at CronJob.start (/home/azer/avaxia-monitpring-app/core-service/node_modules/cron/lib/cron.js:613:31)
    at new CronJob (/home/azer/avaxia-monitpring-app/core-service/node_modules/cron/lib/cron.js:576:10)
    at module.exports (/home/azer/avaxia-monitpring-app/core-service/services/task/autoStartTaskCron.js:2:1041)
    at Object.exports.validateTask (/home/azer/avaxia-monitpring-app/core-service/controllers/task.controller.js:11:699)
    at async Context.<anonymous> (/home/azer/avaxia-monitpring-app/core-service/test/unit/task/updateState/validateTask.controller.test.js:51:5)
[2022-01-06T10:22:12.976] [ERROR] ma-core - An unexpected error occurred during auto start task Error: WARNING: Date in past. Will never be fired.
    at CronTime.sendAt (/home/azer/avaxia-monitpring-app/core-service/node_modules/cron/lib/cron.js:148:12)
    at CronTime.getTimeout (/home/azer/avaxia-monitpring-app/core-service/node_modules/cron/lib/cron.js:175:29)
    at CronJob.start (/home/azer/avaxia-monitpring-app/core-service/node_modules/cron/lib/cron.js:613:31)
    at new CronJob (/home/azer/avaxia-monitpring-app/core-service/node_modules/cron/lib/cron.js:576:10)
    at module.exports (/home/azer/avaxia-monitpring-app/core-service/services/task/autoStartTaskCron.js:2:1041)
    at Object.exports.validateTask (/home/azer/avaxia-monitpring-app/core-service/controllers/task.controller.js:11:699)
    at async Context.<anonymous> (/home/azer/avaxia-monitpring-app/core-service/test/unit/task/updateState/validateTask.controller.test.js:95:5)
[2022-01-06T10:22:12.981] [ERROR] ma-core - An unexpected error occurred during auto start task Error: WARNING: Date in past. Will never be fired.
    at CronTime.sendAt (/home/azer/avaxia-monitpring-app/core-service/node_modules/cron/lib/cron.js:148:12)
    at CronTime.getTimeout (/home/azer/avaxia-monitpring-app/core-service/node_modules/cron/lib/cron.js:175:29)
    at CronJob.start (/home/azer/avaxia-monitpring-app/core-service/node_modules/cron/lib/cron.js:613:31)
    at new CronJob (/home/azer/avaxia-monitpring-app/core-service/node_modules/cron/lib/cron.js:576:10)
    at module.exports (/home/azer/avaxia-monitpring-app/core-service/services/task/autoStartTaskCron.js:2:1041)
    at Object.exports.validateTask (/home/azer/avaxia-monitpring-app/core-service/controllers/task.controller.js:11:699)
    at async Context.<anonymous> (/home/azer/avaxia-monitpring-app/core-service/test/unit/task/updateState/validateTask.controller.test.js:176:5)
[2022-01-06T10:22:12.982] [ERROR] ma-core - Failed to validate the Task :failed to update the task testing testing testing
[2022-01-06T10:22:12.984] [ERROR] ma-core - An unexpected error occurred during auto start task Error: WARNING: Date in past. Will never be fired.
    at CronTime.sendAt (/home/azer/avaxia-monitpring-app/core-service/node_modules/cron/lib/cron.js:148:12)
    at CronTime.getTimeout (/home/azer/avaxia-monitpring-app/core-service/node_modules/cron/lib/cron.js:175:29)
    at CronJob.start (/home/azer/avaxia-monitpring-app/core-service/node_modules/cron/lib/cron.js:613:31)
    at new CronJob (/home/azer/avaxia-monitpring-app/core-service/node_modules/cron/lib/cron.js:576:10)
    at module.exports (/home/azer/avaxia-monitpring-app/core-service/services/task/autoStartTaskCron.js:2:1041)
    at Object.exports.validateTask (/home/azer/avaxia-monitpring-app/core-service/controllers/task.controller.js:11:699)
    at async Context.<anonymous> (/home/azer/avaxia-monitpring-app/core-service/test/unit/task/updateState/validateTask.controller.test.js:219:5)
[2022-01-06T10:22:12.984] [ERROR] ma-core - Failed to validate the Task :failed to update the task NaN post 1234
[2022-01-06T10:22:12.995] [ERROR] ma-core - update Task :You are not authorized to perform this action testing testing testing
[2022-01-06T10:22:12.998] [ERROR] ma-core - update Task :task not found NaN post 1234
[2022-01-06T10:25:03.912] [ERROR] ma-core - get All Task By filter error :error testing testing testing
[2022-01-06T10:25:03.919] [ERROR] ma-core - get by id Task :task not found testing testing testing
[2022-01-06T10:25:03.921] [ERROR] ma-core - get by id Task :task not found NaN post 1234
[2022-01-06T10:25:03.934] [ERROR] ma-core - get All Task By filter error :error testing testing testing
[2022-01-06T10:25:04.043] [ERROR] ma-core - get Created Tasks error : error testing testing testing
[2022-01-06T10:25:04.050] [ERROR] ma-core - get Created Tasks error : error NaN post 1234
[2022-01-06T10:25:04.060] [ERROR] ma-core - add Task :missing property testing testing testing
[2022-01-06T10:25:04.061] [ERROR] ma-core - add Task :missing property NaN post 1234
[2022-01-06T10:25:04.076] [ERROR] ma-core - add Many Task :missing property testing testing testing
[2022-01-06T10:25:04.078] [ERROR] ma-core - add Many Task :missing property NaN post 1234
[2022-01-06T10:25:04.096] [ERROR] ma-core - update Task :task not found testing testing testing
[2022-01-06T10:25:04.097] [ERROR] ma-core - update Task :task not found NaN post 1234
[2022-01-06T10:25:04.099] [ERROR] ma-core - Socket.io is not initialized !
[2022-01-06T10:25:04.107] [ERROR] ma-core - Update Task Assignee :task not found testing testing testing
[2022-01-06T10:25:04.125] [ERROR] ma-core - Failed to Cancel the Task :failed to update the task testing testing testing
[2022-01-06T10:25:04.127] [ERROR] ma-core - Failed to Cancel the Task :failed to update the task NaN post 1234
[2022-01-06T10:25:04.135] [ERROR] ma-core - Failed to reject the Task :failed to update the task testing testing testing
[2022-01-06T10:25:04.136] [ERROR] ma-core - Failed to reject the Task :failed to update the task NaN post 1234
[2022-01-06T10:25:04.145] [ERROR] ma-core - Failed to delete the Task :failed to update the task testing testing testing
[2022-01-06T10:25:04.147] [ERROR] ma-core - Failed to delete the Task :failed to update the task NaN post 1234
[2022-01-06T10:25:04.154] [ERROR] ma-core - Failed to finish the Task :failed to update the task testing testing testing
[2022-01-06T10:25:04.156] [ERROR] ma-core - Failed to finish the Task :failed to update the task NaN post 1234
[2022-01-06T10:25:04.163] [ERROR] ma-core - Failed to reject the Task :failed to update the task testing testing testing
[2022-01-06T10:25:04.165] [ERROR] ma-core - Failed to reject the Task :failed to update the task NaN post 1234
[2022-01-06T10:25:04.170] [ERROR] ma-core - An unexpected error occurred during auto start task Error: WARNING: Date in past. Will never be fired.
    at CronTime.sendAt (/home/azer/avaxia-monitpring-app/core-service/node_modules/cron/lib/cron.js:148:12)
    at CronTime.getTimeout (/home/azer/avaxia-monitpring-app/core-service/node_modules/cron/lib/cron.js:175:29)
    at CronJob.start (/home/azer/avaxia-monitpring-app/core-service/node_modules/cron/lib/cron.js:613:31)
    at new CronJob (/home/azer/avaxia-monitpring-app/core-service/node_modules/cron/lib/cron.js:576:10)
    at module.exports (/home/azer/avaxia-monitpring-app/core-service/services/task/autoStartTaskCron.js:2:1041)
    at Object.exports.validateTask (/home/azer/avaxia-monitpring-app/core-service/controllers/task.controller.js:11:699)
    at async Context.<anonymous> (/home/azer/avaxia-monitpring-app/core-service/test/unit/task/updateState/validateTask.controller.test.js:51:5)
[2022-01-06T10:25:04.174] [ERROR] ma-core - An unexpected error occurred during auto start task Error: WARNING: Date in past. Will never be fired.
    at CronTime.sendAt (/home/azer/avaxia-monitpring-app/core-service/node_modules/cron/lib/cron.js:148:12)
    at CronTime.getTimeout (/home/azer/avaxia-monitpring-app/core-service/node_modules/cron/lib/cron.js:175:29)
    at CronJob.start (/home/azer/avaxia-monitpring-app/core-service/node_modules/cron/lib/cron.js:613:31)
    at new CronJob (/home/azer/avaxia-monitpring-app/core-service/node_modules/cron/lib/cron.js:576:10)
    at module.exports (/home/azer/avaxia-monitpring-app/core-service/services/task/autoStartTaskCron.js:2:1041)
    at Object.exports.validateTask (/home/azer/avaxia-monitpring-app/core-service/controllers/task.controller.js:11:699)
    at async Context.<anonymous> (/home/azer/avaxia-monitpring-app/core-service/test/unit/task/updateState/validateTask.controller.test.js:95:5)
[2022-01-06T10:25:04.179] [ERROR] ma-core - An unexpected error occurred during auto start task Error: WARNING: Date in past. Will never be fired.
    at CronTime.sendAt (/home/azer/avaxia-monitpring-app/core-service/node_modules/cron/lib/cron.js:148:12)
    at CronTime.getTimeout (/home/azer/avaxia-monitpring-app/core-service/node_modules/cron/lib/cron.js:175:29)
    at CronJob.start (/home/azer/avaxia-monitpring-app/core-service/node_modules/cron/lib/cron.js:613:31)
    at new CronJob (/home/azer/avaxia-monitpring-app/core-service/node_modules/cron/lib/cron.js:576:10)
    at module.exports (/home/azer/avaxia-monitpring-app/core-service/services/task/autoStartTaskCron.js:2:1041)
    at Object.exports.validateTask (/home/azer/avaxia-monitpring-app/core-service/controllers/task.controller.js:11:699)
    at async Context.<anonymous> (/home/azer/avaxia-monitpring-app/core-service/test/unit/task/updateState/validateTask.controller.test.js:176:5)
[2022-01-06T10:25:04.179] [ERROR] ma-core - Failed to validate the Task :failed to update the task testing testing testing
[2022-01-06T10:25:04.182] [ERROR] ma-core - An unexpected error occurred during auto start task Error: WARNING: Date in past. Will never be fired.
    at CronTime.sendAt (/home/azer/avaxia-monitpring-app/core-service/node_modules/cron/lib/cron.js:148:12)
    at CronTime.getTimeout (/home/azer/avaxia-monitpring-app/core-service/node_modules/cron/lib/cron.js:175:29)
    at CronJob.start (/home/azer/avaxia-monitpring-app/core-service/node_modules/cron/lib/cron.js:613:31)
    at new CronJob (/home/azer/avaxia-monitpring-app/core-service/node_modules/cron/lib/cron.js:576:10)
    at module.exports (/home/azer/avaxia-monitpring-app/core-service/services/task/autoStartTaskCron.js:2:1041)
    at Object.exports.validateTask (/home/azer/avaxia-monitpring-app/core-service/controllers/task.controller.js:11:699)
    at async Context.<anonymous> (/home/azer/avaxia-monitpring-app/core-service/test/unit/task/updateState/validateTask.controller.test.js:219:5)
[2022-01-06T10:25:04.183] [ERROR] ma-core - Failed to validate the Task :failed to update the task NaN post 1234
[2022-01-06T10:25:04.194] [ERROR] ma-core - update Task :You are not authorized to perform this action testing testing testing
[2022-01-06T10:25:04.197] [ERROR] ma-core - update Task :task not found NaN post 1234
[2022-01-06T10:34:24.671] [ERROR] ma-core - get All Task By filter error :error testing testing testing
[2022-01-06T10:34:24.681] [ERROR] ma-core - get by id Task :task not found testing testing testing
[2022-01-06T10:34:24.683] [ERROR] ma-core - get by id Task :task not found NaN post 1234
[2022-01-06T10:34:24.696] [ERROR] ma-core - get All Task By filter error :error testing testing testing
[2022-01-06T10:34:24.812] [ERROR] ma-core - get Created Tasks error : error testing testing testing
[2022-01-06T10:34:24.816] [ERROR] ma-core - get Created Tasks error : error NaN post 1234
[2022-01-06T10:34:24.826] [ERROR] ma-core - add Task :missing property testing testing testing
[2022-01-06T10:34:24.828] [ERROR] ma-core - add Task :missing property NaN post 1234
[2022-01-06T10:34:24.843] [ERROR] ma-core - add Many Task :missing property testing testing testing
[2022-01-06T10:34:24.845] [ERROR] ma-core - add Many Task :missing property NaN post 1234
[2022-01-06T10:34:24.863] [ERROR] ma-core - update Task :task not found testing testing testing
[2022-01-06T10:34:24.864] [ERROR] ma-core - update Task :task not found NaN post 1234
[2022-01-06T10:34:24.866] [ERROR] ma-core - Socket.io is not initialized !
[2022-01-06T10:34:24.876] [ERROR] ma-core - Update Task Assignee :task not found testing testing testing
[2022-01-06T10:34:24.894] [ERROR] ma-core - Failed to Cancel the Task :failed to update the task testing testing testing
[2022-01-06T10:34:24.896] [ERROR] ma-core - Failed to Cancel the Task :failed to update the task NaN post 1234
[2022-01-06T10:34:24.906] [ERROR] ma-core - Failed to reject the Task :failed to update the task testing testing testing
[2022-01-06T10:34:24.908] [ERROR] ma-core - Failed to reject the Task :failed to update the task NaN post 1234
[2022-01-06T10:34:24.916] [ERROR] ma-core - Failed to delete the Task :failed to update the task testing testing testing
[2022-01-06T10:34:24.918] [ERROR] ma-core - Failed to delete the Task :failed to update the task NaN post 1234
[2022-01-06T10:34:24.927] [ERROR] ma-core - Failed to finish the Task :failed to update the task testing testing testing
[2022-01-06T10:34:24.929] [ERROR] ma-core - Failed to finish the Task :failed to update the task NaN post 1234
[2022-01-06T10:34:24.938] [ERROR] ma-core - Failed to reject the Task :failed to update the task testing testing testing
[2022-01-06T10:34:24.940] [ERROR] ma-core - Failed to reject the Task :failed to update the task NaN post 1234
[2022-01-06T10:34:24.943] [ERROR] ma-core - An unexpected error occurred during auto start task Error: WARNING: Date in past. Will never be fired.
    at CronTime.sendAt (/home/azer/avaxia-monitpring-app/core-service/node_modules/cron/lib/cron.js:148:12)
    at CronTime.getTimeout (/home/azer/avaxia-monitpring-app/core-service/node_modules/cron/lib/cron.js:175:29)
    at CronJob.start (/home/azer/avaxia-monitpring-app/core-service/node_modules/cron/lib/cron.js:613:31)
    at new CronJob (/home/azer/avaxia-monitpring-app/core-service/node_modules/cron/lib/cron.js:576:10)
    at module.exports (/home/azer/avaxia-monitpring-app/core-service/services/task/autoStartTaskCron.js:2:1041)
    at Object.exports.validateTask (/home/azer/avaxia-monitpring-app/core-service/controllers/task.controller.js:11:699)
    at async Context.<anonymous> (/home/azer/avaxia-monitpring-app/core-service/test/unit/task/updateState/validateTask.controller.test.js:51:5)
[2022-01-06T10:34:24.947] [ERROR] ma-core - An unexpected error occurred during auto start task Error: WARNING: Date in past. Will never be fired.
    at CronTime.sendAt (/home/azer/avaxia-monitpring-app/core-service/node_modules/cron/lib/cron.js:148:12)
    at CronTime.getTimeout (/home/azer/avaxia-monitpring-app/core-service/node_modules/cron/lib/cron.js:175:29)
    at CronJob.start (/home/azer/avaxia-monitpring-app/core-service/node_modules/cron/lib/cron.js:613:31)
    at new CronJob (/home/azer/avaxia-monitpring-app/core-service/node_modules/cron/lib/cron.js:576:10)
    at module.exports (/home/azer/avaxia-monitpring-app/core-service/services/task/autoStartTaskCron.js:2:1041)
    at Object.exports.validateTask (/home/azer/avaxia-monitpring-app/core-service/controllers/task.controller.js:11:699)
    at async Context.<anonymous> (/home/azer/avaxia-monitpring-app/core-service/test/unit/task/updateState/validateTask.controller.test.js:95:5)
[2022-01-06T10:34:24.952] [ERROR] ma-core - An unexpected error occurred during auto start task Error: WARNING: Date in past. Will never be fired.
    at CronTime.sendAt (/home/azer/avaxia-monitpring-app/core-service/node_modules/cron/lib/cron.js:148:12)
    at CronTime.getTimeout (/home/azer/avaxia-monitpring-app/core-service/node_modules/cron/lib/cron.js:175:29)
    at CronJob.start (/home/azer/avaxia-monitpring-app/core-service/node_modules/cron/lib/cron.js:613:31)
    at new CronJob (/home/azer/avaxia-monitpring-app/core-service/node_modules/cron/lib/cron.js:576:10)
    at module.exports (/home/azer/avaxia-monitpring-app/core-service/services/task/autoStartTaskCron.js:2:1041)
    at Object.exports.validateTask (/home/azer/avaxia-monitpring-app/core-service/controllers/task.controller.js:11:699)
    at async Context.<anonymous> (/home/azer/avaxia-monitpring-app/core-service/test/unit/task/updateState/validateTask.controller.test.js:176:5)
[2022-01-06T10:34:24.953] [ERROR] ma-core - Failed to validate the Task :failed to update the task testing testing testing
[2022-01-06T10:34:24.955] [ERROR] ma-core - An unexpected error occurred during auto start task Error: WARNING: Date in past. Will never be fired.
    at CronTime.sendAt (/home/azer/avaxia-monitpring-app/core-service/node_modules/cron/lib/cron.js:148:12)
    at CronTime.getTimeout (/home/azer/avaxia-monitpring-app/core-service/node_modules/cron/lib/cron.js:175:29)
    at CronJob.start (/home/azer/avaxia-monitpring-app/core-service/node_modules/cron/lib/cron.js:613:31)
    at new CronJob (/home/azer/avaxia-monitpring-app/core-service/node_modules/cron/lib/cron.js:576:10)
    at module.exports (/home/azer/avaxia-monitpring-app/core-service/services/task/autoStartTaskCron.js:2:1041)
    at Object.exports.validateTask (/home/azer/avaxia-monitpring-app/core-service/controllers/task.controller.js:11:699)
    at async Context.<anonymous> (/home/azer/avaxia-monitpring-app/core-service/test/unit/task/updateState/validateTask.controller.test.js:219:5)
[2022-01-06T10:34:24.956] [ERROR] ma-core - Failed to validate the Task :failed to update the task NaN post 1234
[2022-01-06T10:34:24.968] [ERROR] ma-core - update Task :You are not authorized to perform this action testing testing testing
[2022-01-06T10:34:24.971] [ERROR] ma-core - update Task :task not found NaN post 1234
[2022-01-06T10:37:29.829] [ERROR] ma-core - get All Task By filter error :error testing testing testing
[2022-01-06T10:37:29.841] [ERROR] ma-core - get by id Task :task not found testing testing testing
[2022-01-06T10:37:29.843] [ERROR] ma-core - get by id Task :task not found NaN post 1234
[2022-01-06T10:37:29.853] [ERROR] ma-core - get All Task By filter error :error testing testing testing
[2022-01-06T10:37:29.958] [ERROR] ma-core - get Created Tasks error : error testing testing testing
[2022-01-06T10:37:29.963] [ERROR] ma-core - get Created Tasks error : error NaN post 1234
[2022-01-06T10:37:29.974] [ERROR] ma-core - add Task :missing property testing testing testing
[2022-01-06T10:37:29.976] [ERROR] ma-core - add Task :missing property NaN post 1234
[2022-01-06T10:37:29.989] [ERROR] ma-core - add Many Task :missing property testing testing testing
[2022-01-06T10:37:29.992] [ERROR] ma-core - add Many Task :missing property NaN post 1234
[2022-01-06T10:37:30.010] [ERROR] ma-core - update Task :task not found testing testing testing
[2022-01-06T10:37:30.011] [ERROR] ma-core - update Task :task not found NaN post 1234
[2022-01-06T10:37:30.013] [ERROR] ma-core - Socket.io is not initialized !
[2022-01-06T10:37:30.022] [ERROR] ma-core - Update Task Assignee :task not found testing testing testing
[2022-01-06T10:37:30.038] [ERROR] ma-core - Failed to Cancel the Task :failed to update the task testing testing testing
[2022-01-06T10:37:30.039] [ERROR] ma-core - Failed to Cancel the Task :failed to update the task NaN post 1234
[2022-01-06T10:37:30.050] [ERROR] ma-core - Failed to reject the Task :failed to update the task testing testing testing
[2022-01-06T10:37:30.052] [ERROR] ma-core - Failed to reject the Task :failed to update the task NaN post 1234
[2022-01-06T10:37:30.060] [ERROR] ma-core - Failed to delete the Task :failed to update the task testing testing testing
[2022-01-06T10:37:30.062] [ERROR] ma-core - Failed to delete the Task :failed to update the task NaN post 1234
[2022-01-06T10:37:30.069] [ERROR] ma-core - Failed to finish the Task :failed to update the task testing testing testing
[2022-01-06T10:37:30.071] [ERROR] ma-core - Failed to finish the Task :failed to update the task NaN post 1234
[2022-01-06T10:37:30.080] [ERROR] ma-core - Failed to reject the Task :failed to update the task testing testing testing
[2022-01-06T10:37:30.081] [ERROR] ma-core - Failed to reject the Task :failed to update the task NaN post 1234
[2022-01-06T10:37:30.086] [ERROR] ma-core - An unexpected error occurred during auto start task Error: WARNING: Date in past. Will never be fired.
    at CronTime.sendAt (/home/azer/avaxia-monitpring-app/core-service/node_modules/cron/lib/cron.js:148:12)
    at CronTime.getTimeout (/home/azer/avaxia-monitpring-app/core-service/node_modules/cron/lib/cron.js:175:29)
    at CronJob.start (/home/azer/avaxia-monitpring-app/core-service/node_modules/cron/lib/cron.js:613:31)
    at new CronJob (/home/azer/avaxia-monitpring-app/core-service/node_modules/cron/lib/cron.js:576:10)
    at module.exports (/home/azer/avaxia-monitpring-app/core-service/services/task/autoStartTaskCron.js:2:1041)
    at Object.exports.validateTask (/home/azer/avaxia-monitpring-app/core-service/controllers/task.controller.js:11:699)
    at async Context.<anonymous> (/home/azer/avaxia-monitpring-app/core-service/test/unit/task/updateState/validateTask.controller.test.js:51:5)
[2022-01-06T10:37:30.091] [ERROR] ma-core - An unexpected error occurred during auto start task Error: WARNING: Date in past. Will never be fired.
    at CronTime.sendAt (/home/azer/avaxia-monitpring-app/core-service/node_modules/cron/lib/cron.js:148:12)
    at CronTime.getTimeout (/home/azer/avaxia-monitpring-app/core-service/node_modules/cron/lib/cron.js:175:29)
    at CronJob.start (/home/azer/avaxia-monitpring-app/core-service/node_modules/cron/lib/cron.js:613:31)
    at new CronJob (/home/azer/avaxia-monitpring-app/core-service/node_modules/cron/lib/cron.js:576:10)
    at module.exports (/home/azer/avaxia-monitpring-app/core-service/services/task/autoStartTaskCron.js:2:1041)
    at Object.exports.validateTask (/home/azer/avaxia-monitpring-app/core-service/controllers/task.controller.js:11:699)
    at async Context.<anonymous> (/home/azer/avaxia-monitpring-app/core-service/test/unit/task/updateState/validateTask.controller.test.js:95:5)
[2022-01-06T10:37:30.097] [ERROR] ma-core - An unexpected error occurred during auto start task Error: WARNING: Date in past. Will never be fired.
    at CronTime.sendAt (/home/azer/avaxia-monitpring-app/core-service/node_modules/cron/lib/cron.js:148:12)
    at CronTime.getTimeout (/home/azer/avaxia-monitpring-app/core-service/node_modules/cron/lib/cron.js:175:29)
    at CronJob.start (/home/azer/avaxia-monitpring-app/core-service/node_modules/cron/lib/cron.js:613:31)
    at new CronJob (/home/azer/avaxia-monitpring-app/core-service/node_modules/cron/lib/cron.js:576:10)
    at module.exports (/home/azer/avaxia-monitpring-app/core-service/services/task/autoStartTaskCron.js:2:1041)
    at Object.exports.validateTask (/home/azer/avaxia-monitpring-app/core-service/controllers/task.controller.js:11:699)
    at async Context.<anonymous> (/home/azer/avaxia-monitpring-app/core-service/test/unit/task/updateState/validateTask.controller.test.js:176:5)
[2022-01-06T10:37:30.097] [ERROR] ma-core - Failed to validate the Task :failed to update the task testing testing testing
[2022-01-06T10:37:30.100] [ERROR] ma-core - An unexpected error occurred during auto start task Error: WARNING: Date in past. Will never be fired.
    at CronTime.sendAt (/home/azer/avaxia-monitpring-app/core-service/node_modules/cron/lib/cron.js:148:12)
    at CronTime.getTimeout (/home/azer/avaxia-monitpring-app/core-service/node_modules/cron/lib/cron.js:175:29)
    at CronJob.start (/home/azer/avaxia-monitpring-app/core-service/node_modules/cron/lib/cron.js:613:31)
    at new CronJob (/home/azer/avaxia-monitpring-app/core-service/node_modules/cron/lib/cron.js:576:10)
    at module.exports (/home/azer/avaxia-monitpring-app/core-service/services/task/autoStartTaskCron.js:2:1041)
    at Object.exports.validateTask (/home/azer/avaxia-monitpring-app/core-service/controllers/task.controller.js:11:699)
    at async Context.<anonymous> (/home/azer/avaxia-monitpring-app/core-service/test/unit/task/updateState/validateTask.controller.test.js:219:5)
[2022-01-06T10:37:30.100] [ERROR] ma-core - Failed to validate the Task :failed to update the task NaN post 1234
[2022-01-06T10:37:30.111] [ERROR] ma-core - update Task :You are not authorized to perform this action testing testing testing
[2022-01-06T10:37:30.115] [ERROR] ma-core - update Task :task not found NaN post 1234
[2022-01-06T10:39:18.295] [ERROR] ma-core - get All Task By filter error :error testing testing testing
[2022-01-06T10:39:18.304] [ERROR] ma-core - get by id Task :task not found testing testing testing
[2022-01-06T10:39:18.306] [ERROR] ma-core - get by id Task :task not found NaN post 1234
[2022-01-06T10:39:18.314] [ERROR] ma-core - get All Task By filter error :error testing testing testing
[2022-01-06T10:39:18.417] [ERROR] ma-core - get Created Tasks error : error testing testing testing
[2022-01-06T10:39:18.421] [ERROR] ma-core - get Created Tasks error : error NaN post 1234
[2022-01-06T10:39:18.437] [ERROR] ma-core - add Task :missing property testing testing testing
[2022-01-06T10:39:18.438] [ERROR] ma-core - add Task :missing property NaN post 1234
[2022-01-06T10:39:18.452] [ERROR] ma-core - add Many Task :missing property testing testing testing
[2022-01-06T10:39:18.454] [ERROR] ma-core - add Many Task :missing property NaN post 1234
[2022-01-06T10:39:18.472] [ERROR] ma-core - update Task :task not found testing testing testing
[2022-01-06T10:39:18.474] [ERROR] ma-core - update Task :task not found NaN post 1234
[2022-01-06T10:39:18.476] [ERROR] ma-core - Socket.io is not initialized !
[2022-01-06T10:39:18.486] [ERROR] ma-core - Update Task Assignee :task not found testing testing testing
[2022-01-06T10:39:18.502] [ERROR] ma-core - Failed to Cancel the Task :failed to update the task testing testing testing
[2022-01-06T10:39:18.503] [ERROR] ma-core - Failed to Cancel the Task :failed to update the task NaN post 1234
[2022-01-06T10:39:18.512] [ERROR] ma-core - Failed to reject the Task :failed to update the task testing testing testing
[2022-01-06T10:39:18.513] [ERROR] ma-core - Failed to reject the Task :failed to update the task NaN post 1234
[2022-01-06T10:39:18.524] [ERROR] ma-core - Failed to delete the Task :failed to update the task testing testing testing
[2022-01-06T10:39:18.526] [ERROR] ma-core - Failed to delete the Task :failed to update the task NaN post 1234
[2022-01-06T10:39:18.534] [ERROR] ma-core - Failed to finish the Task :failed to update the task testing testing testing
[2022-01-06T10:39:18.536] [ERROR] ma-core - Failed to finish the Task :failed to update the task NaN post 1234
[2022-01-06T10:39:18.545] [ERROR] ma-core - Failed to reject the Task :failed to update the task testing testing testing
[2022-01-06T10:39:18.547] [ERROR] ma-core - Failed to reject the Task :failed to update the task NaN post 1234
[2022-01-06T10:39:18.554] [ERROR] ma-core - An unexpected error occurred during auto start task Error: WARNING: Date in past. Will never be fired.
    at CronTime.sendAt (/home/azer/avaxia-monitpring-app/core-service/node_modules/cron/lib/cron.js:148:12)
    at CronTime.getTimeout (/home/azer/avaxia-monitpring-app/core-service/node_modules/cron/lib/cron.js:175:29)
    at CronJob.start (/home/azer/avaxia-monitpring-app/core-service/node_modules/cron/lib/cron.js:613:31)
    at new CronJob (/home/azer/avaxia-monitpring-app/core-service/node_modules/cron/lib/cron.js:576:10)
    at module.exports (/home/azer/avaxia-monitpring-app/core-service/services/task/autoStartTaskCron.js:2:1041)
    at Object.exports.validateTask (/home/azer/avaxia-monitpring-app/core-service/controllers/task.controller.js:11:699)
    at async Context.<anonymous> (/home/azer/avaxia-monitpring-app/core-service/test/unit/task/updateState/validateTask.controller.test.js:51:5)
[2022-01-06T10:39:18.559] [ERROR] ma-core - An unexpected error occurred during auto start task Error: WARNING: Date in past. Will never be fired.
    at CronTime.sendAt (/home/azer/avaxia-monitpring-app/core-service/node_modules/cron/lib/cron.js:148:12)
    at CronTime.getTimeout (/home/azer/avaxia-monitpring-app/core-service/node_modules/cron/lib/cron.js:175:29)
    at CronJob.start (/home/azer/avaxia-monitpring-app/core-service/node_modules/cron/lib/cron.js:613:31)
    at new CronJob (/home/azer/avaxia-monitpring-app/core-service/node_modules/cron/lib/cron.js:576:10)
    at module.exports (/home/azer/avaxia-monitpring-app/core-service/services/task/autoStartTaskCron.js:2:1041)
    at Object.exports.validateTask (/home/azer/avaxia-monitpring-app/core-service/controllers/task.controller.js:11:699)
    at async Context.<anonymous> (/home/azer/avaxia-monitpring-app/core-service/test/unit/task/updateState/validateTask.controller.test.js:95:5)
[2022-01-06T10:39:18.564] [ERROR] ma-core - An unexpected error occurred during auto start task Error: WARNING: Date in past. Will never be fired.
    at CronTime.sendAt (/home/azer/avaxia-monitpring-app/core-service/node_modules/cron/lib/cron.js:148:12)
    at CronTime.getTimeout (/home/azer/avaxia-monitpring-app/core-service/node_modules/cron/lib/cron.js:175:29)
    at CronJob.start (/home/azer/avaxia-monitpring-app/core-service/node_modules/cron/lib/cron.js:613:31)
    at new CronJob (/home/azer/avaxia-monitpring-app/core-service/node_modules/cron/lib/cron.js:576:10)
    at module.exports (/home/azer/avaxia-monitpring-app/core-service/services/task/autoStartTaskCron.js:2:1041)
    at Object.exports.validateTask (/home/azer/avaxia-monitpring-app/core-service/controllers/task.controller.js:11:699)
    at async Context.<anonymous> (/home/azer/avaxia-monitpring-app/core-service/test/unit/task/updateState/validateTask.controller.test.js:176:5)
[2022-01-06T10:39:18.565] [ERROR] ma-core - Failed to validate the Task :failed to update the task testing testing testing
[2022-01-06T10:39:18.567] [ERROR] ma-core - An unexpected error occurred during auto start task Error: WARNING: Date in past. Will never be fired.
    at CronTime.sendAt (/home/azer/avaxia-monitpring-app/core-service/node_modules/cron/lib/cron.js:148:12)
    at CronTime.getTimeout (/home/azer/avaxia-monitpring-app/core-service/node_modules/cron/lib/cron.js:175:29)
    at CronJob.start (/home/azer/avaxia-monitpring-app/core-service/node_modules/cron/lib/cron.js:613:31)
    at new CronJob (/home/azer/avaxia-monitpring-app/core-service/node_modules/cron/lib/cron.js:576:10)
    at module.exports (/home/azer/avaxia-monitpring-app/core-service/services/task/autoStartTaskCron.js:2:1041)
    at Object.exports.validateTask (/home/azer/avaxia-monitpring-app/core-service/controllers/task.controller.js:11:699)
    at async Context.<anonymous> (/home/azer/avaxia-monitpring-app/core-service/test/unit/task/updateState/validateTask.controller.test.js:219:5)
[2022-01-06T10:39:18.568] [ERROR] ma-core - Failed to validate the Task :failed to update the task NaN post 1234
[2022-01-06T10:39:18.580] [ERROR] ma-core - update Task :You are not authorized to perform this action testing testing testing
[2022-01-06T10:39:18.583] [ERROR] ma-core - update Task :task not found NaN post 1234
[2022-01-06T10:42:56.909] [ERROR] ma-core - get All Task By filter error :error testing testing testing
[2022-01-06T10:42:56.918] [ERROR] ma-core - get by id Task :task not found testing testing testing
[2022-01-06T10:42:56.920] [ERROR] ma-core - get by id Task :task not found NaN post 1234
[2022-01-06T10:42:56.929] [ERROR] ma-core - get All Task By filter error :error testing testing testing
[2022-01-06T10:42:57.034] [ERROR] ma-core - get Created Tasks error : error testing testing testing
[2022-01-06T10:42:57.039] [ERROR] ma-core - get Created Tasks error : error NaN post 1234
[2022-01-06T10:42:57.050] [ERROR] ma-core - add Task :missing property testing testing testing
[2022-01-06T10:42:57.052] [ERROR] ma-core - add Task :missing property NaN post 1234
[2022-01-06T10:42:57.064] [ERROR] ma-core - add Many Task :missing property testing testing testing
[2022-01-06T10:42:57.066] [ERROR] ma-core - add Many Task :missing property NaN post 1234
[2022-01-06T10:42:57.084] [ERROR] ma-core - update Task :task not found testing testing testing
[2022-01-06T10:42:57.085] [ERROR] ma-core - update Task :task not found NaN post 1234
[2022-01-06T10:42:57.087] [ERROR] ma-core - Socket.io is not initialized !
[2022-01-06T10:42:57.098] [ERROR] ma-core - Update Task Assignee :task not found testing testing testing
[2022-01-06T10:42:57.121] [ERROR] ma-core - Failed to Cancel the Task :failed to update the task testing testing testing
[2022-01-06T10:42:57.123] [ERROR] ma-core - Failed to Cancel the Task :failed to update the task NaN post 1234
[2022-01-06T10:42:57.131] [ERROR] ma-core - Failed to reject the Task :failed to update the task testing testing testing
[2022-01-06T10:42:57.132] [ERROR] ma-core - Failed to reject the Task :failed to update the task NaN post 1234
[2022-01-06T10:42:57.142] [ERROR] ma-core - Failed to delete the Task :failed to update the task testing testing testing
[2022-01-06T10:42:57.144] [ERROR] ma-core - Failed to delete the Task :failed to update the task NaN post 1234
[2022-01-06T10:42:57.152] [ERROR] ma-core - Failed to finish the Task :failed to update the task testing testing testing
[2022-01-06T10:42:57.154] [ERROR] ma-core - Failed to finish the Task :failed to update the task NaN post 1234
[2022-01-06T10:42:57.162] [ERROR] ma-core - Failed to reject the Task :failed to update the task testing testing testing
[2022-01-06T10:42:57.164] [ERROR] ma-core - Failed to reject the Task :failed to update the task NaN post 1234
[2022-01-06T10:42:57.168] [ERROR] ma-core - An unexpected error occurred during auto start task Error: WARNING: Date in past. Will never be fired.
    at CronTime.sendAt (/home/azer/avaxia-monitpring-app/core-service/node_modules/cron/lib/cron.js:148:12)
    at CronTime.getTimeout (/home/azer/avaxia-monitpring-app/core-service/node_modules/cron/lib/cron.js:175:29)
    at CronJob.start (/home/azer/avaxia-monitpring-app/core-service/node_modules/cron/lib/cron.js:613:31)
    at new CronJob (/home/azer/avaxia-monitpring-app/core-service/node_modules/cron/lib/cron.js:576:10)
    at module.exports (/home/azer/avaxia-monitpring-app/core-service/services/task/autoStartTaskCron.js:2:1041)
    at Object.exports.validateTask (/home/azer/avaxia-monitpring-app/core-service/controllers/task.controller.js:11:699)
    at async Context.<anonymous> (/home/azer/avaxia-monitpring-app/core-service/test/unit/task/updateState/validateTask.controller.test.js:51:5)
[2022-01-06T10:42:57.173] [ERROR] ma-core - An unexpected error occurred during auto start task Error: WARNING: Date in past. Will never be fired.
    at CronTime.sendAt (/home/azer/avaxia-monitpring-app/core-service/node_modules/cron/lib/cron.js:148:12)
    at CronTime.getTimeout (/home/azer/avaxia-monitpring-app/core-service/node_modules/cron/lib/cron.js:175:29)
    at CronJob.start (/home/azer/avaxia-monitpring-app/core-service/node_modules/cron/lib/cron.js:613:31)
    at new CronJob (/home/azer/avaxia-monitpring-app/core-service/node_modules/cron/lib/cron.js:576:10)
    at module.exports (/home/azer/avaxia-monitpring-app/core-service/services/task/autoStartTaskCron.js:2:1041)
    at Object.exports.validateTask (/home/azer/avaxia-monitpring-app/core-service/controllers/task.controller.js:11:699)
    at async Context.<anonymous> (/home/azer/avaxia-monitpring-app/core-service/test/unit/task/updateState/validateTask.controller.test.js:95:5)
[2022-01-06T10:42:57.178] [ERROR] ma-core - An unexpected error occurred during auto start task Error: WARNING: Date in past. Will never be fired.
    at CronTime.sendAt (/home/azer/avaxia-monitpring-app/core-service/node_modules/cron/lib/cron.js:148:12)
    at CronTime.getTimeout (/home/azer/avaxia-monitpring-app/core-service/node_modules/cron/lib/cron.js:175:29)
    at CronJob.start (/home/azer/avaxia-monitpring-app/core-service/node_modules/cron/lib/cron.js:613:31)
    at new CronJob (/home/azer/avaxia-monitpring-app/core-service/node_modules/cron/lib/cron.js:576:10)
    at module.exports (/home/azer/avaxia-monitpring-app/core-service/services/task/autoStartTaskCron.js:2:1041)
    at Object.exports.validateTask (/home/azer/avaxia-monitpring-app/core-service/controllers/task.controller.js:11:699)
    at async Context.<anonymous> (/home/azer/avaxia-monitpring-app/core-service/test/unit/task/updateState/validateTask.controller.test.js:176:5)
[2022-01-06T10:42:57.179] [ERROR] ma-core - Failed to validate the Task :failed to update the task testing testing testing
[2022-01-06T10:42:57.181] [ERROR] ma-core - An unexpected error occurred during auto start task Error: WARNING: Date in past. Will never be fired.
    at CronTime.sendAt (/home/azer/avaxia-monitpring-app/core-service/node_modules/cron/lib/cron.js:148:12)
    at CronTime.getTimeout (/home/azer/avaxia-monitpring-app/core-service/node_modules/cron/lib/cron.js:175:29)
    at CronJob.start (/home/azer/avaxia-monitpring-app/core-service/node_modules/cron/lib/cron.js:613:31)
    at new CronJob (/home/azer/avaxia-monitpring-app/core-service/node_modules/cron/lib/cron.js:576:10)
    at module.exports (/home/azer/avaxia-monitpring-app/core-service/services/task/autoStartTaskCron.js:2:1041)
    at Object.exports.validateTask (/home/azer/avaxia-monitpring-app/core-service/controllers/task.controller.js:11:699)
    at async Context.<anonymous> (/home/azer/avaxia-monitpring-app/core-service/test/unit/task/updateState/validateTask.controller.test.js:219:5)
[2022-01-06T10:42:57.181] [ERROR] ma-core - Failed to validate the Task :failed to update the task NaN post 1234
[2022-01-06T10:42:57.195] [ERROR] ma-core - update Task :You are not authorized to perform this action testing testing testing
[2022-01-06T10:42:57.199] [ERROR] ma-core - update Task :task not found NaN post 1234
[2022-01-06T14:22:17.180] [ERROR] ma-core - get All Task By filter error :error testing testing testing
[2022-01-06T14:22:17.191] [ERROR] ma-core - get by id Task :task not found testing testing testing
[2022-01-06T14:22:17.194] [ERROR] ma-core - get by id Task :task not found NaN post 1234
[2022-01-06T14:22:17.207] [ERROR] ma-core - get All Task By filter error :error testing testing testing
[2022-01-06T14:22:17.341] [ERROR] ma-core - get Created Tasks error : error testing testing testing
[2022-01-06T14:22:17.347] [ERROR] ma-core - get Created Tasks error : error NaN post 1234
[2022-01-06T14:22:17.360] [ERROR] ma-core - add Task :missing property testing testing testing
[2022-01-06T14:22:17.361] [ERROR] ma-core - add Task :missing property NaN post 1234
[2022-01-06T14:22:17.382] [ERROR] ma-core - add Many Task :missing property testing testing testing
[2022-01-06T14:22:17.383] [ERROR] ma-core - add Many Task :missing property NaN post 1234
[2022-01-06T14:22:17.408] [ERROR] ma-core - update Task :task not found testing testing testing
[2022-01-06T14:22:17.411] [ERROR] ma-core - update Task :task not found NaN post 1234
[2022-01-06T14:22:17.413] [ERROR] ma-core - Socket.io is not initialized !
[2022-01-06T14:22:17.426] [ERROR] ma-core - Update Task Assignee :task not found testing testing testing
[2022-01-06T14:22:17.448] [ERROR] ma-core - Failed to Cancel the Task :failed to update the task testing testing testing
[2022-01-06T14:22:17.449] [ERROR] ma-core - Failed to Cancel the Task :failed to update the task NaN post 1234
[2022-01-06T14:22:17.460] [ERROR] ma-core - Failed to reject the Task :failed to update the task testing testing testing
[2022-01-06T14:22:17.462] [ERROR] ma-core - Failed to reject the Task :failed to update the task NaN post 1234
[2022-01-06T14:22:17.474] [ERROR] ma-core - Failed to delete the Task :failed to update the task testing testing testing
[2022-01-06T14:22:17.476] [ERROR] ma-core - Failed to delete the Task :failed to update the task NaN post 1234
[2022-01-06T14:22:17.484] [ERROR] ma-core - Failed to finish the Task :failed to update the task testing testing testing
[2022-01-06T14:22:17.487] [ERROR] ma-core - Failed to finish the Task :failed to update the task NaN post 1234
[2022-01-06T14:22:17.500] [ERROR] ma-core - Failed to reject the Task :failed to update the task testing testing testing
[2022-01-06T14:22:17.502] [ERROR] ma-core - Failed to reject the Task :failed to update the task NaN post 1234
[2022-01-06T14:22:17.508] [ERROR] ma-core - An unexpected error occurred during auto start task Error: WARNING: Date in past. Will never be fired.
    at CronTime.sendAt (/home/azer/avaxia-monitpring-app/core-service/node_modules/cron/lib/cron.js:148:12)
    at CronTime.getTimeout (/home/azer/avaxia-monitpring-app/core-service/node_modules/cron/lib/cron.js:175:29)
    at CronJob.start (/home/azer/avaxia-monitpring-app/core-service/node_modules/cron/lib/cron.js:613:31)
    at new CronJob (/home/azer/avaxia-monitpring-app/core-service/node_modules/cron/lib/cron.js:576:10)
    at module.exports (/home/azer/avaxia-monitpring-app/core-service/services/task/autoStartTaskCron.js:2:1041)
    at Object.exports.validateTask (/home/azer/avaxia-monitpring-app/core-service/controllers/task.controller.js:11:699)
    at async Context.<anonymous> (/home/azer/avaxia-monitpring-app/core-service/test/unit/task/updateState/validateTask.controller.test.js:51:5)
[2022-01-06T14:22:17.513] [ERROR] ma-core - An unexpected error occurred during auto start task Error: WARNING: Date in past. Will never be fired.
    at CronTime.sendAt (/home/azer/avaxia-monitpring-app/core-service/node_modules/cron/lib/cron.js:148:12)
    at CronTime.getTimeout (/home/azer/avaxia-monitpring-app/core-service/node_modules/cron/lib/cron.js:175:29)
    at CronJob.start (/home/azer/avaxia-monitpring-app/core-service/node_modules/cron/lib/cron.js:613:31)
    at new CronJob (/home/azer/avaxia-monitpring-app/core-service/node_modules/cron/lib/cron.js:576:10)
    at module.exports (/home/azer/avaxia-monitpring-app/core-service/services/task/autoStartTaskCron.js:2:1041)
    at Object.exports.validateTask (/home/azer/avaxia-monitpring-app/core-service/controllers/task.controller.js:11:699)
    at async Context.<anonymous> (/home/azer/avaxia-monitpring-app/core-service/test/unit/task/updateState/validateTask.controller.test.js:95:5)
[2022-01-06T14:22:17.521] [ERROR] ma-core - An unexpected error occurred during auto start task Error: WARNING: Date in past. Will never be fired.
    at CronTime.sendAt (/home/azer/avaxia-monitpring-app/core-service/node_modules/cron/lib/cron.js:148:12)
    at CronTime.getTimeout (/home/azer/avaxia-monitpring-app/core-service/node_modules/cron/lib/cron.js:175:29)
    at CronJob.start (/home/azer/avaxia-monitpring-app/core-service/node_modules/cron/lib/cron.js:613:31)
    at new CronJob (/home/azer/avaxia-monitpring-app/core-service/node_modules/cron/lib/cron.js:576:10)
    at module.exports (/home/azer/avaxia-monitpring-app/core-service/services/task/autoStartTaskCron.js:2:1041)
    at Object.exports.validateTask (/home/azer/avaxia-monitpring-app/core-service/controllers/task.controller.js:11:699)
    at async Context.<anonymous> (/home/azer/avaxia-monitpring-app/core-service/test/unit/task/updateState/validateTask.controller.test.js:176:5)
[2022-01-06T14:22:17.522] [ERROR] ma-core - Failed to validate the Task :failed to update the task testing testing testing
[2022-01-06T14:22:17.526] [ERROR] ma-core - An unexpected error occurred during auto start task Error: WARNING: Date in past. Will never be fired.
    at CronTime.sendAt (/home/azer/avaxia-monitpring-app/core-service/node_modules/cron/lib/cron.js:148:12)
    at CronTime.getTimeout (/home/azer/avaxia-monitpring-app/core-service/node_modules/cron/lib/cron.js:175:29)
    at CronJob.start (/home/azer/avaxia-monitpring-app/core-service/node_modules/cron/lib/cron.js:613:31)
    at new CronJob (/home/azer/avaxia-monitpring-app/core-service/node_modules/cron/lib/cron.js:576:10)
    at module.exports (/home/azer/avaxia-monitpring-app/core-service/services/task/autoStartTaskCron.js:2:1041)
    at Object.exports.validateTask (/home/azer/avaxia-monitpring-app/core-service/controllers/task.controller.js:11:699)
    at async Context.<anonymous> (/home/azer/avaxia-monitpring-app/core-service/test/unit/task/updateState/validateTask.controller.test.js:219:5)
[2022-01-06T14:22:17.526] [ERROR] ma-core - Failed to validate the Task :failed to update the task NaN post 1234
[2022-01-06T14:22:17.548] [ERROR] ma-core - update Task :You are not authorized to perform this action testing testing testing
[2022-01-06T14:22:17.552] [ERROR] ma-core - update Task :task not found NaN post 1234
[2022-01-06T15:36:30.980] [ERROR] ma-core - get All Task By filter error :error testing testing testing
[2022-01-06T15:36:30.988] [ERROR] ma-core - get by id Task :task not found testing testing testing
[2022-01-06T15:36:30.990] [ERROR] ma-core - get by id Task :task not found NaN post 1234
[2022-01-06T15:36:30.999] [ERROR] ma-core - get All Task By filter error :error testing testing testing
[2022-01-06T15:36:31.100] [ERROR] ma-core - get Created Tasks error : error testing testing testing
[2022-01-06T15:36:31.104] [ERROR] ma-core - get Created Tasks error : error NaN post 1234
[2022-01-06T15:36:31.115] [ERROR] ma-core - add Task :missing property testing testing testing
[2022-01-06T15:36:31.117] [ERROR] ma-core - add Task :missing property NaN post 1234
[2022-01-06T15:36:31.132] [ERROR] ma-core - add Many Task :missing property testing testing testing
[2022-01-06T15:36:31.133] [ERROR] ma-core - add Many Task :missing property NaN post 1234
[2022-01-06T15:36:31.151] [ERROR] ma-core - update Task :task not found testing testing testing
[2022-01-06T15:36:31.152] [ERROR] ma-core - update Task :task not found NaN post 1234
[2022-01-06T15:36:31.154] [ERROR] ma-core - Socket.io is not initialized !
[2022-01-06T15:36:31.165] [ERROR] ma-core - Update Task Assignee :task not found testing testing testing
[2022-01-06T15:36:31.181] [ERROR] ma-core - Failed to Cancel the Task :failed to update the task testing testing testing
[2022-01-06T15:36:31.183] [ERROR] ma-core - Failed to Cancel the Task :failed to update the task NaN post 1234
[2022-01-06T15:36:31.191] [ERROR] ma-core - Failed to reject the Task :failed to update the task testing testing testing
[2022-01-06T15:36:31.193] [ERROR] ma-core - Failed to reject the Task :failed to update the task NaN post 1234
[2022-01-06T15:36:31.201] [ERROR] ma-core - Failed to delete the Task :failed to update the task testing testing testing
[2022-01-06T15:36:31.202] [ERROR] ma-core - Failed to delete the Task :failed to update the task NaN post 1234
[2022-01-06T15:36:31.211] [ERROR] ma-core - Failed to finish the Task :failed to update the task testing testing testing
[2022-01-06T15:36:31.213] [ERROR] ma-core - Failed to finish the Task :failed to update the task NaN post 1234
[2022-01-06T15:36:31.221] [ERROR] ma-core - Failed to reject the Task :failed to update the task testing testing testing
[2022-01-06T15:36:31.223] [ERROR] ma-core - Failed to reject the Task :failed to update the task NaN post 1234
[2022-01-06T15:36:31.227] [ERROR] ma-core - An unexpected error occurred during auto start task Error: WARNING: Date in past. Will never be fired.
    at CronTime.sendAt (/home/azer/avaxia-monitpring-app/core-service/node_modules/cron/lib/cron.js:148:12)
    at CronTime.getTimeout (/home/azer/avaxia-monitpring-app/core-service/node_modules/cron/lib/cron.js:175:29)
    at CronJob.start (/home/azer/avaxia-monitpring-app/core-service/node_modules/cron/lib/cron.js:613:31)
    at new CronJob (/home/azer/avaxia-monitpring-app/core-service/node_modules/cron/lib/cron.js:576:10)
    at module.exports (/home/azer/avaxia-monitpring-app/core-service/services/task/autoStartTaskCron.js:2:1041)
    at Object.exports.validateTask (/home/azer/avaxia-monitpring-app/core-service/controllers/task.controller.js:11:699)
    at async Context.<anonymous> (/home/azer/avaxia-monitpring-app/core-service/test/unit/task/updateState/validateTask.controller.test.js:51:5)
[2022-01-06T15:36:31.230] [ERROR] ma-core - An unexpected error occurred during auto start task Error: WARNING: Date in past. Will never be fired.
    at CronTime.sendAt (/home/azer/avaxia-monitpring-app/core-service/node_modules/cron/lib/cron.js:148:12)
    at CronTime.getTimeout (/home/azer/avaxia-monitpring-app/core-service/node_modules/cron/lib/cron.js:175:29)
    at CronJob.start (/home/azer/avaxia-monitpring-app/core-service/node_modules/cron/lib/cron.js:613:31)
    at new CronJob (/home/azer/avaxia-monitpring-app/core-service/node_modules/cron/lib/cron.js:576:10)
    at module.exports (/home/azer/avaxia-monitpring-app/core-service/services/task/autoStartTaskCron.js:2:1041)
    at Object.exports.validateTask (/home/azer/avaxia-monitpring-app/core-service/controllers/task.controller.js:11:699)
    at async Context.<anonymous> (/home/azer/avaxia-monitpring-app/core-service/test/unit/task/updateState/validateTask.controller.test.js:95:5)
[2022-01-06T15:36:31.240] [ERROR] ma-core - An unexpected error occurred during auto start task Error: WARNING: Date in past. Will never be fired.
    at CronTime.sendAt (/home/azer/avaxia-monitpring-app/core-service/node_modules/cron/lib/cron.js:148:12)
    at CronTime.getTimeout (/home/azer/avaxia-monitpring-app/core-service/node_modules/cron/lib/cron.js:175:29)
    at CronJob.start (/home/azer/avaxia-monitpring-app/core-service/node_modules/cron/lib/cron.js:613:31)
    at new CronJob (/home/azer/avaxia-monitpring-app/core-service/node_modules/cron/lib/cron.js:576:10)
    at module.exports (/home/azer/avaxia-monitpring-app/core-service/services/task/autoStartTaskCron.js:2:1041)
    at Object.exports.validateTask (/home/azer/avaxia-monitpring-app/core-service/controllers/task.controller.js:11:699)
    at async Context.<anonymous> (/home/azer/avaxia-monitpring-app/core-service/test/unit/task/updateState/validateTask.controller.test.js:176:5)
[2022-01-06T15:36:31.241] [ERROR] ma-core - Failed to validate the Task :failed to update the task testing testing testing
[2022-01-06T15:36:31.243] [ERROR] ma-core - An unexpected error occurred during auto start task Error: WARNING: Date in past. Will never be fired.
    at CronTime.sendAt (/home/azer/avaxia-monitpring-app/core-service/node_modules/cron/lib/cron.js:148:12)
    at CronTime.getTimeout (/home/azer/avaxia-monitpring-app/core-service/node_modules/cron/lib/cron.js:175:29)
    at CronJob.start (/home/azer/avaxia-monitpring-app/core-service/node_modules/cron/lib/cron.js:613:31)
    at new CronJob (/home/azer/avaxia-monitpring-app/core-service/node_modules/cron/lib/cron.js:576:10)
    at module.exports (/home/azer/avaxia-monitpring-app/core-service/services/task/autoStartTaskCron.js:2:1041)
    at Object.exports.validateTask (/home/azer/avaxia-monitpring-app/core-service/controllers/task.controller.js:11:699)
    at async Context.<anonymous> (/home/azer/avaxia-monitpring-app/core-service/test/unit/task/updateState/validateTask.controller.test.js:219:5)
[2022-01-06T15:36:31.244] [ERROR] ma-core - Failed to validate the Task :failed to update the task NaN post 1234
[2022-01-06T15:36:31.257] [ERROR] ma-core - update Task :You are not authorized to perform this action testing testing testing
[2022-01-06T15:36:31.261] [ERROR] ma-core - update Task :task not found NaN post 1234
[2022-01-06T15:40:42.040] [ERROR] ma-core - get All Task By filter error :error testing testing testing
[2022-01-06T15:40:42.047] [ERROR] ma-core - get by id Task :task not found testing testing testing
[2022-01-06T15:40:42.049] [ERROR] ma-core - get by id Task :task not found NaN post 1234
[2022-01-06T15:40:42.058] [ERROR] ma-core - get All Task By filter error :error testing testing testing
[2022-01-06T15:40:42.163] [ERROR] ma-core - get Created Tasks error : error testing testing testing
[2022-01-06T15:40:42.167] [ERROR] ma-core - get Created Tasks error : error NaN post 1234
[2022-01-06T15:40:42.181] [ERROR] ma-core - add Task :missing property testing testing testing
[2022-01-06T15:40:42.183] [ERROR] ma-core - add Task :missing property NaN post 1234
[2022-01-06T15:40:42.195] [ERROR] ma-core - add Many Task :missing property testing testing testing
[2022-01-06T15:40:42.196] [ERROR] ma-core - add Many Task :missing property NaN post 1234
[2022-01-06T15:40:42.214] [ERROR] ma-core - update Task :task not found testing testing testing
[2022-01-06T15:40:42.215] [ERROR] ma-core - update Task :task not found NaN post 1234
[2022-01-06T15:40:42.217] [ERROR] ma-core - Socket.io is not initialized !
[2022-01-06T15:40:42.218] [ERROR] ma-core - Socket.io is not initialized !
[2022-01-06T15:40:42.228] [ERROR] ma-core - Update Task Assignee :task not found testing testing testing
[2022-01-06T15:40:42.244] [ERROR] ma-core - Failed to Cancel the Task :failed to update the task testing testing testing
[2022-01-06T15:40:42.246] [ERROR] ma-core - Failed to Cancel the Task :failed to update the task NaN post 1234
[2022-01-06T15:40:42.253] [ERROR] ma-core - Failed to reject the Task :failed to update the task testing testing testing
[2022-01-06T15:40:42.255] [ERROR] ma-core - Failed to reject the Task :failed to update the task NaN post 1234
[2022-01-06T15:40:42.263] [ERROR] ma-core - Failed to delete the Task :failed to update the task testing testing testing
[2022-01-06T15:40:42.265] [ERROR] ma-core - Failed to delete the Task :failed to update the task NaN post 1234
[2022-01-06T15:40:42.274] [ERROR] ma-core - Failed to finish the Task :failed to update the task testing testing testing
[2022-01-06T15:40:42.275] [ERROR] ma-core - Failed to finish the Task :failed to update the task NaN post 1234
[2022-01-06T15:40:42.286] [ERROR] ma-core - Failed to reject the Task :failed to update the task testing testing testing
[2022-01-06T15:40:42.288] [ERROR] ma-core - Failed to reject the Task :failed to update the task NaN post 1234
[2022-01-06T15:40:42.292] [ERROR] ma-core - An unexpected error occurred during auto start task Error: WARNING: Date in past. Will never be fired.
    at CronTime.sendAt (/home/azer/avaxia-monitpring-app/core-service/node_modules/cron/lib/cron.js:148:12)
    at CronTime.getTimeout (/home/azer/avaxia-monitpring-app/core-service/node_modules/cron/lib/cron.js:175:29)
    at CronJob.start (/home/azer/avaxia-monitpring-app/core-service/node_modules/cron/lib/cron.js:613:31)
    at new CronJob (/home/azer/avaxia-monitpring-app/core-service/node_modules/cron/lib/cron.js:576:10)
    at module.exports (/home/azer/avaxia-monitpring-app/core-service/services/task/autoStartTaskCron.js:2:1041)
    at Object.exports.validateTask (/home/azer/avaxia-monitpring-app/core-service/controllers/task.controller.js:11:699)
    at async Context.<anonymous> (/home/azer/avaxia-monitpring-app/core-service/test/unit/task/updateState/validateTask.controller.test.js:51:5)
[2022-01-06T15:40:42.295] [ERROR] ma-core - An unexpected error occurred during auto start task Error: WARNING: Date in past. Will never be fired.
    at CronTime.sendAt (/home/azer/avaxia-monitpring-app/core-service/node_modules/cron/lib/cron.js:148:12)
    at CronTime.getTimeout (/home/azer/avaxia-monitpring-app/core-service/node_modules/cron/lib/cron.js:175:29)
    at CronJob.start (/home/azer/avaxia-monitpring-app/core-service/node_modules/cron/lib/cron.js:613:31)
    at new CronJob (/home/azer/avaxia-monitpring-app/core-service/node_modules/cron/lib/cron.js:576:10)
    at module.exports (/home/azer/avaxia-monitpring-app/core-service/services/task/autoStartTaskCron.js:2:1041)
    at Object.exports.validateTask (/home/azer/avaxia-monitpring-app/core-service/controllers/task.controller.js:11:699)
    at async Context.<anonymous> (/home/azer/avaxia-monitpring-app/core-service/test/unit/task/updateState/validateTask.controller.test.js:95:5)
[2022-01-06T15:40:42.301] [ERROR] ma-core - An unexpected error occurred during auto start task Error: WARNING: Date in past. Will never be fired.
    at CronTime.sendAt (/home/azer/avaxia-monitpring-app/core-service/node_modules/cron/lib/cron.js:148:12)
    at CronTime.getTimeout (/home/azer/avaxia-monitpring-app/core-service/node_modules/cron/lib/cron.js:175:29)
    at CronJob.start (/home/azer/avaxia-monitpring-app/core-service/node_modules/cron/lib/cron.js:613:31)
    at new CronJob (/home/azer/avaxia-monitpring-app/core-service/node_modules/cron/lib/cron.js:576:10)
    at module.exports (/home/azer/avaxia-monitpring-app/core-service/services/task/autoStartTaskCron.js:2:1041)
    at Object.exports.validateTask (/home/azer/avaxia-monitpring-app/core-service/controllers/task.controller.js:11:699)
    at async Context.<anonymous> (/home/azer/avaxia-monitpring-app/core-service/test/unit/task/updateState/validateTask.controller.test.js:176:5)
[2022-01-06T15:40:42.301] [ERROR] ma-core - Failed to validate the Task :failed to update the task testing testing testing
[2022-01-06T15:40:42.305] [ERROR] ma-core - An unexpected error occurred during auto start task Error: WARNING: Date in past. Will never be fired.
    at CronTime.sendAt (/home/azer/avaxia-monitpring-app/core-service/node_modules/cron/lib/cron.js:148:12)
    at CronTime.getTimeout (/home/azer/avaxia-monitpring-app/core-service/node_modules/cron/lib/cron.js:175:29)
    at CronJob.start (/home/azer/avaxia-monitpring-app/core-service/node_modules/cron/lib/cron.js:613:31)
    at new CronJob (/home/azer/avaxia-monitpring-app/core-service/node_modules/cron/lib/cron.js:576:10)
    at module.exports (/home/azer/avaxia-monitpring-app/core-service/services/task/autoStartTaskCron.js:2:1041)
    at Object.exports.validateTask (/home/azer/avaxia-monitpring-app/core-service/controllers/task.controller.js:11:699)
    at async Context.<anonymous> (/home/azer/avaxia-monitpring-app/core-service/test/unit/task/updateState/validateTask.controller.test.js:219:5)
[2022-01-06T15:40:42.305] [ERROR] ma-core - Failed to validate the Task :failed to update the task NaN post 1234
[2022-01-06T15:40:42.317] [ERROR] ma-core - update Task :You are not authorized to perform this action testing testing testing
[2022-01-06T15:40:42.320] [ERROR] ma-core - update Task :task not found NaN post 1234
[2022-01-06T16:39:01.793] [ERROR] ma-core - get All Task By filter error :error testing testing testing
[2022-01-06T16:39:01.801] [ERROR] ma-core - get by id Task :task not found testing testing testing
[2022-01-06T16:39:01.803] [ERROR] ma-core - get by id Task :task not found NaN post 1234
[2022-01-06T16:39:01.813] [ERROR] ma-core - get All Task By filter error :error testing testing testing
[2022-01-06T16:39:01.917] [ERROR] ma-core - get Created Tasks error : error testing testing testing
[2022-01-06T16:39:01.922] [ERROR] ma-core - get Created Tasks error : error NaN post 1234
[2022-01-06T16:39:01.934] [ERROR] ma-core - add Task :missing property testing testing testing
[2022-01-06T16:39:01.935] [ERROR] ma-core - add Task :missing property NaN post 1234
[2022-01-06T16:39:01.947] [ERROR] ma-core - add Many Task :missing property testing testing testing
[2022-01-06T16:39:01.949] [ERROR] ma-core - add Many Task :missing property NaN post 1234
[2022-01-06T16:39:01.968] [ERROR] ma-core - update Task :task not found testing testing testing
[2022-01-06T16:39:01.969] [ERROR] ma-core - update Task :task not found NaN post 1234
[2022-01-06T16:39:01.971] [ERROR] ma-core - Socket.io is not initialized !
[2022-01-06T16:39:01.971] [ERROR] ma-core - Socket.io is not initialized !
[2022-01-06T16:39:01.985] [ERROR] ma-core - Update Task Assignee :task not found testing testing testing
[2022-01-06T16:39:02.004] [ERROR] ma-core - Failed to Cancel the Task :failed to update the task testing testing testing
[2022-01-06T16:39:02.005] [ERROR] ma-core - Failed to Cancel the Task :failed to update the task NaN post 1234
[2022-01-06T16:39:02.013] [ERROR] ma-core - Failed to reject the Task :failed to update the task testing testing testing
[2022-01-06T16:39:02.015] [ERROR] ma-core - Failed to reject the Task :failed to update the task NaN post 1234
[2022-01-06T16:39:02.025] [ERROR] ma-core - Failed to delete the Task :failed to update the task testing testing testing
[2022-01-06T16:39:02.027] [ERROR] ma-core - Failed to delete the Task :failed to update the task NaN post 1234
[2022-01-06T16:39:02.034] [ERROR] ma-core - Failed to finish the Task :failed to update the task testing testing testing
[2022-01-06T16:39:02.036] [ERROR] ma-core - Failed to finish the Task :failed to update the task NaN post 1234
[2022-01-06T16:39:02.045] [ERROR] ma-core - Failed to reject the Task :failed to update the task testing testing testing
[2022-01-06T16:39:02.047] [ERROR] ma-core - Failed to reject the Task :failed to update the task NaN post 1234
[2022-01-06T16:39:02.051] [ERROR] ma-core - An unexpected error occurred during auto start task Error: WARNING: Date in past. Will never be fired.
    at CronTime.sendAt (/home/azer/avaxia-monitpring-app/core-service/node_modules/cron/lib/cron.js:148:12)
    at CronTime.getTimeout (/home/azer/avaxia-monitpring-app/core-service/node_modules/cron/lib/cron.js:175:29)
    at CronJob.start (/home/azer/avaxia-monitpring-app/core-service/node_modules/cron/lib/cron.js:613:31)
    at new CronJob (/home/azer/avaxia-monitpring-app/core-service/node_modules/cron/lib/cron.js:576:10)
    at module.exports (/home/azer/avaxia-monitpring-app/core-service/services/task/autoStartTaskCron.js:2:1041)
    at Object.exports.validateTask (/home/azer/avaxia-monitpring-app/core-service/controllers/task.controller.js:11:699)
    at async Context.<anonymous> (/home/azer/avaxia-monitpring-app/core-service/test/unit/task/updateState/validateTask.controller.test.js:51:5)
[2022-01-06T16:39:02.056] [ERROR] ma-core - An unexpected error occurred during auto start task Error: WARNING: Date in past. Will never be fired.
    at CronTime.sendAt (/home/azer/avaxia-monitpring-app/core-service/node_modules/cron/lib/cron.js:148:12)
    at CronTime.getTimeout (/home/azer/avaxia-monitpring-app/core-service/node_modules/cron/lib/cron.js:175:29)
    at CronJob.start (/home/azer/avaxia-monitpring-app/core-service/node_modules/cron/lib/cron.js:613:31)
    at new CronJob (/home/azer/avaxia-monitpring-app/core-service/node_modules/cron/lib/cron.js:576:10)
    at module.exports (/home/azer/avaxia-monitpring-app/core-service/services/task/autoStartTaskCron.js:2:1041)
    at Object.exports.validateTask (/home/azer/avaxia-monitpring-app/core-service/controllers/task.controller.js:11:699)
    at async Context.<anonymous> (/home/azer/avaxia-monitpring-app/core-service/test/unit/task/updateState/validateTask.controller.test.js:95:5)
[2022-01-06T16:39:02.062] [ERROR] ma-core - An unexpected error occurred during auto start task Error: WARNING: Date in past. Will never be fired.
    at CronTime.sendAt (/home/azer/avaxia-monitpring-app/core-service/node_modules/cron/lib/cron.js:148:12)
    at CronTime.getTimeout (/home/azer/avaxia-monitpring-app/core-service/node_modules/cron/lib/cron.js:175:29)
    at CronJob.start (/home/azer/avaxia-monitpring-app/core-service/node_modules/cron/lib/cron.js:613:31)
    at new CronJob (/home/azer/avaxia-monitpring-app/core-service/node_modules/cron/lib/cron.js:576:10)
    at module.exports (/home/azer/avaxia-monitpring-app/core-service/services/task/autoStartTaskCron.js:2:1041)
    at Object.exports.validateTask (/home/azer/avaxia-monitpring-app/core-service/controllers/task.controller.js:11:699)
    at async Context.<anonymous> (/home/azer/avaxia-monitpring-app/core-service/test/unit/task/updateState/validateTask.controller.test.js:176:5)
[2022-01-06T16:39:02.062] [ERROR] ma-core - Failed to validate the Task :failed to update the task testing testing testing
[2022-01-06T16:39:02.065] [ERROR] ma-core - An unexpected error occurred during auto start task Error: WARNING: Date in past. Will never be fired.
    at CronTime.sendAt (/home/azer/avaxia-monitpring-app/core-service/node_modules/cron/lib/cron.js:148:12)
    at CronTime.getTimeout (/home/azer/avaxia-monitpring-app/core-service/node_modules/cron/lib/cron.js:175:29)
    at CronJob.start (/home/azer/avaxia-monitpring-app/core-service/node_modules/cron/lib/cron.js:613:31)
    at new CronJob (/home/azer/avaxia-monitpring-app/core-service/node_modules/cron/lib/cron.js:576:10)
    at module.exports (/home/azer/avaxia-monitpring-app/core-service/services/task/autoStartTaskCron.js:2:1041)
    at Object.exports.validateTask (/home/azer/avaxia-monitpring-app/core-service/controllers/task.controller.js:11:699)
    at async Context.<anonymous> (/home/azer/avaxia-monitpring-app/core-service/test/unit/task/updateState/validateTask.controller.test.js:219:5)
[2022-01-06T16:39:02.065] [ERROR] ma-core - Failed to validate the Task :failed to update the task NaN post 1234
[2022-01-06T16:39:02.079] [ERROR] ma-core - update Task :You are not authorized to perform this action testing testing testing
[2022-01-06T16:39:02.083] [ERROR] ma-core - update Task :task not found NaN post 1234
